Workbook

Sheet Einteilung A-Junioren
A1: Einteilung A-Junioren 2025/2026 | H1: Stand: 30.07.25
A3: SL: | B3: Karl Ruck
A4: A-Junioren Regionenstaffel Nord 1
A5: 1. | B5: FSV Friedrichshaller SV
A6: 2. | B6: SGM Neckarwestheim I
A7: 3. | B7: SGM TSV Hardthausen KoBra
A8: 4. | B8: SGM TSV Michelfeld/Juniorteam MMB
A9: 5. | B9: SGM Union Heilbronn / TSN 1969
A10: 6. | B10: SGM VfR Gommersdorf/Mittleres Jagsttal I
A11: 7. | B11: Sport-Union Neckarsulm
A12: 8. | B12: SpVgg Satteldorf
A13: 9. | B13: TSV Ilshofen
A14: 10. | B14: TV Flein
A17: SL: | B17: Reiner Falk | D17: SL: | E17: Reiner Falk | G17: SL: | H17: Karl Ruck
A18: A-Junioren Qualistaffel 1 | D18: A-Junioren Qualistaffel 2 | G18: A-Junioren Qualistaffel 3
A19: 1. | B19: SGM Cleebronn/Botenheim/Eibensbach/Stockheim | D19: 1. | E19: Aramäer Heilbronn | G19: 1. | H19: SC Michelbach/Wald
A20: 2. | B20: SGM Dürrenzimmern Unteres Zabergäu | D20: 2. | E20: SC Amorbach | G20: 2. | H20: SC Steinbach
A21: 3. | B21: SGM Kirchhausen | D21: 3. | E21: SG Bad Wimpfen | G21: 3. | H21: SGM SSV Schwäbisch Hall/Tura Untermünkheim
A22: 4. | B22: SGM Lehrensteinsfeld | D22: 4. | E22: SGM Höchstberg H-U-T-H I | G22: 4. | H22: SGM SV Berlichingen/Schöntal/Mittleres Kochertal
A23: 5. | B23: SGM SC Abstatt/Beilstein/Ilsfeld/Heinriet ABI | D23: 5. | E23: SGM Neuenstadt Kochertal | G23: 5. | H23: SGM TSV Kupferzell/Gaisbach/Ingelfingen
A24: 6. | B24: SGM TSV Meimsheim Neckar/Zabergäu | D24: 6. | E24: SGM Obergriesheim Krumme Ebene am Neckar | G24: 6. | H24: SGM TSV Schwabbach/Brettachtal
A25: 7. | B25: SV Leingarten | D25: 7. | E25: TG Böckingen | G25: 7. | H25: SGM VfB Neuhütten/Wüstenrot/Neulautern
A26: 8. | B26: TSV Untergruppenbach | D26: 8. | E26: TSG Heilbronn | G26: 8. | H26: SGM VfR Gommersdorf/Mittleres Jagsttal II
A27: 9. | B27: TSV Weinsberg
A30: SL: | B30: Karl Ruck | D30: SL: | E30: Karl Ruck | G30: SL: | H30: Reiner Falk
A31: A-Junioren Qualistaffel 4 | D31: A-Junioren Qualistaffel 5 | G31: A-Junioren Qualistaffel 6 (Topf 2)
A32: 1. | B32: SGM Bühlerzell/Bühlertann | D32: 1. | E32: SGM Dünsbach/Blaufelden/Gerabronn/Billingsbach | G32: 1. | H32: SC Böckingen
A33: 2. | B33: SGM Eutendorf/Ottendorf | D33: 2. | E33: SGM FC Creglingen/Oberes Taubertal | G33: 2. | H33: SGM Bonfeld/Fürfeld/Obergimpern (flex)
A34: 3. | B34: SGM Oberrot/Rottal | D34: 3. | E34: SGM Hengstfeld/Rot am See/Brettheim | G34: 3. | H34: SGM Ellhofen Sulmtal (flex)
A35: 4. | B35: SGM Sulzdorf/Hessental | D35: 4. | E35: SGM TSV Schrozberg / Gammesfeld / Bartenstein | G35: 4. | H35: SGM Höchstberg H-U-T-H II (flex)
A36: 5. | B36: SGM Vellberg/Obersontheim/Gründelh.-Operspeltach/Honhardt | D36: 5. | E36: SGM Weikersheim Vorbach-Tauber | G36: 5. | H36: SGM Neckarwestheim II
A37: 6. | B37: SGM VfR Altenmünster/SV Onolzheim | D37: 6. | E37: SGM VfB Bad Mergentheim /1. FC Igersheim | G37: 6. | H37: SGM Oberes Zabergäu/Mühlbach/Sulzfeld
A38: 7. | B38: TSV Crailsheim | D38: 7. | E38: TSG Kirchberg/Jagst | G38: 7. | H38: SGM TSV Niederhofen/Oberes Leintal (flex)
A39: 8. | B39: TSV Gaildorf (flex) | D39: 8. | E39: TV Niederstetten (flex) | G39: 8. | H39: SSV Auenstein
G40: 9. | H40: SV Heilbronn am Leinbach (flex)

Sheet Einteilung B-Junioren
A1: Einteilung B-Junioren 2025/2026 | H1: Stand: 30.07.25
A3: SL: | B3: Bernhard Nied
A4: B-Junioren Regionenstaffel Nord 1
A5: 1. | B5: SGM Bühlerzell/Bühlertann
A6: 2. | B6: SGM Eibensbach/Cleebronn/Botenheim/Stockheim I
A7: 3. | B7: SGM VfR Gommersdorf/Mittleres Jagsttal
A8: 4. | B8: Spfr Neckarwestheim I
A9: 5. | B9: Spfr Schwäbisch Hall
A10: 6. | B10: Sport-Union Neckarsulm
A11: 7. | B11: SpVgg Satteldorf
A12: 8. | B12: TSG Öhringen
A13: 9. | B13: TSV Crailsheim
A14: 10. | B14: TV Flein
A17: SL: | B17: Bernhard Nied | D17: SL: | E17: Bernhard Nied | G17: SL: | H17: Franz Schmitt
A18: B-Junioren Qualistaffel 1 | D18: B-Junioren Qualistaffel 2 | G18: B-Junioren Qualistaffel 3
A19: 1. | B19: FSV Friedrichshaller SV | D19: 1. | E19: SGM Ellhofen Sulmtal | G19: 1. | H19: 1. FC Igersheim
A20: 2. | B20: SC Amorbach | D20: 2. | E20: SGM Hausen Unteres Zabergäu I | G20: 2. | H20: SGM FC Creglingen/Bieberehren/Röttingen/Taubertal (flex)
A21: 3. | B21: SG Bad Wimpfen I | D21: 3. | E21: SGM SG Stetten-Kleingartach/Oberes Leintal I | G21: 3. | H21: SGM Hengstfeld/Rot am See/Brettheim
A22: 4. | B22: SGM Oedheim Kochertal I | D22: 4. | E22: SGM Spfr. Lauffen Neckar/Zabergäu | G22: 4. | H22: SGM SpVgg Gammesfeld/Schrozberg/Bartenstein
A23: 5. | B23: SGM TSV Neudenau Unteres Jagsttal I | D23: 5. | E23: SGM TGV Eintracht Beilstein/Abstatt/Ilsfeld/Heinriet ABI | G23: 5. | H23: SGM SV Wachbach/TSV Althausen-Neunkirchen (flex)
A24: 6. | B24: SGM VfL Eberstadt EbErG | D24: 6. | E24: Spfr Neckarwestheim II | G24: 6. | H24: SGM Weikersheim Vorbach-Tauber
A25: 7. | B25: SV Heilbronn am Leinbach I | D25: 7. | E25: SV Leingarten | G25: 7. | H25: TV Niederstetten
A26: 8. | B26: TG Böckingen | D26: 8. | E26: SV Schluchtern U17 | G26: 8. | H26: VfB Bad Mergentheim
A27: 9. | B27: TSG Heilbronn | D27: 9. | E27: TSV Weinsberg
A28: 10. | B28: VfL Obereisesheim
A31: SL: | B31: Franz Schmitt | D31: SL: | E31: Franz Schmitt | G31: SL: | H31: Christian Reuter
A32: B-Junioren Qualistaffel 4 | D32: B-Junioren Qualistaffel 5 | G32: B-Junioren Qualistaffel 6
A33: 1. | B33: SC Michelbach/Wald | D33: 1. | E33: SC Steinbach | G33: 1. | H33: SGM FC Langenburg/Blaufelden/Braunsbach/Dünsbach I
A34: 2. | B34: SGM SV Westernhausen/ Schöntal | D34: 2. | E34: SG Ottendorf / Eutendorf / SG Rottal | G34: 2. | H34: SGM Fichtenau (flex)
A35: 3. | B35: SGM TSV Ingelfingen/Gaisbach/Kupferzell | D35: 3. | E35: SGM SV Westheim / TSV Michelbach-Bilz / SV Rieden | G35: 3. | H35: SGM Gründelhardt-Oberspeltach/Honhardt/Obersontheim/Vellberg
A36: 4. | B36: SGM TSV Neuenstein/Waldenburg | D36: 4. | E36: SGM TSV Hessental/TSV Sulzdorf | G36: 4. | H36: SGM SV Ingersheim/SSV Stimpfach
A37: 5. | B37: SGM TSV Niedernhall I / Kickers Mittleres Kochertal | D37: 5. | E37: SGM TSV Pfedelbach/Jugendteam TSV I | G37: 5. | H37: SGM VfR Altenmünster/SV Onolzheim
A38: 6. | B38: SGM TSV Ohrnberg / Zweiflingen | D38: 6. | E38: SGM VfL Mainhardt/Juniorteam MMB I | G38: 6. | H38: SGM Westgartshausen /Tiefenbach/Kressberg/Goldbach/Satteldorf
A39: 7. | B39: SGM TSV Pfedelbach/Jugendteam TSV II | D39: 7. | E39: SSV Schwäbisch Hall | G39: 7. | H39: SV Tüngental
A40: 8. | B40: SGM TSV Schwabbach/Brettachtal | D40: 8. | E40: TSV Gaildorf (flex) | G40: 8. | H40: TSV Ilshofen
A44: SL: | B44: Bernhard Nied | D44: SL: | E44: Bernhard Nied | G44: SL: | H44: Franz Schmitt
A45: B-Junioren Qualistaffel 7 (Topf 2) | D45: B-Junioren Qualistaffel 8 (Doppelrunde - Topf 2) | G45: B-Junioren Qualistaffel 9 (Topf 2)
A46: 1. | B46: SC Böckingen (flex) | D46: 1. | E46: SG Bad Wimpfen II | G46: 1. | H46: SGM FC Langenburg/Blaufelden/Braunsbach/Dünsbach II
A47: 2. | B47: SGM Eibensbach/Cleebronn/Botenheim/Stockheim II | D47: 2. | E47: SGM Oedheim Kochertal II (flex) | G47: 2. | H47: SGM FV Künzelsau/SV Morsbach/SC Amrichshausen (flex)
A48: 3. | B48: SGM Hausen Unteres Zabergäu II (flex) | D48: 3. | E48: SGM TSV Brettach KoBra (flex) | G48: 3. | H48: SGM TSV Niedernhall II / Kickers Mittleres Kochertal (flex)
...

Sheet Einteilung C-Junioren
A1: Einteilung C-Junioren 2025/2026 | H1: Stand: 30.07.25
A3: SL: | B3: Franz Schmitt
A4: C-Junioren Regionenstaffel Nord 1
A5: 1. | B5: SGM Botenheim/Cleebronn/Eibensbach/Stockheim I
A6: 2. | B6: SGM FSV Hollenbach II/Mittleres Jagsttal
A7: 3. | B7: SGM SC Bibersfeld/Juniorteam MMB
A8: 4. | B8: SGM SSV Gaisbach/Kupferzell/Ingelfingen I
A9: 5. | B9: SGM TSV Pfedelbach/Jugendteam TSV I
A10: 6. | B10: Spfr Neckarwestheim
A11: 7. | B11: Sport-Union Neckarsulm
A12: 8. | B12: SpVgg Satteldorf I
A13: 9. | B13: SV Heilbronn am Leinbach I
A14: 10. | B14: TSV Crailsheim
A17: SL: | B17: Peter Parys-Allweiler | D17: SL: | E17: Peter Parys-Allweiler | G17: SL: | H17: Peter Parys-Allweiler
A18: C-Junioren Qualistaffel 01 | D18: C-Junioren Qualistaffel 02 | G18: C-Junioren Qualistaffel 03
A19: 1. | B19: FSV Friedrichshaller SV | D19: 1. | E19: SC Amorbach II | G19: 1. | H19: SGM FSV Schwaigern/Oberes Leintal I
A20: 2. | B20: SC Amorbach I | D20: 2. | E20: SGM Dahenfeld/Oedheim I | G20: 2. | H20: SGM Pfaffenhofen / Oberes Zabergäu
A21: 3. | B21: SG Bad Wimpfen | D21: 3. | E21: SGM Spvgg Möckmühl Unteres Jagsttal I | G21: 3. | H21: SGM SC Ilsfeld/Abstatt/Beilstein/Heinriet ABI I
A22: 4. | B22: SGM Gundelsheim Krumme Ebene am Neckar | D22: 4. | E22: SGM Tiefenbach H-U-T-H | G22: 4. | H22: SGM TSV Meimsheim Zabergäu
A23: 5. | B23: SGM Heinsheim/Sommerberg | D23: 5. | E23: SGM TSV Erlenbach EbErG I | G23: 5. | H23: Spfr Lauffen
A24: 6. | B24: SGM Union Heilbronn / TSN 1969 II | D24: 6. | E24: SGM TSV Hardthausen KoBra | G24: 6. | H24: SV Leingarten
A25: 7. | B25: TSG Heilbronn I | D25: 7. | E25: SGM Willsbach I | G25: 7. | H25: TG Böckingen
A26: 8. | B26: VfL Obereisesheim | D26: 8. | E26: TSV Weinsberg | G26: 8. | H26: TV Flein
A29: SL: | B29: Andreas Leitner | D29: SL: | E29: Andreas Leitner | G29: SL: | H29: Andreas Leitner
A30: C-Junioren Qualistaffel 04 | D30: C-Junioren Qualistaffel 05 | G30: C-Junioren Qualistaffel 06
A31: 1. | B31: 1. FC Igersheim | D31: 1. | E31: SGM DJK-TSV Bieringen/Schöntal | G31: 1. | H31: SC Steinbach
A32: 2. | B32: SGM Billingsbach / Blaufelden / Wiesenbach | D32: 2. | E32: SGM FV Künzelsau / SV Morsbach / SC Amrichshausen | G32: 2. | H32: SGM Eutendorf/Ottendorf
A33: 3. | B33: SGM FC Creglingen/Oberes Taubertal | D33: 3. | E33: SGM TSG Waldenburg/TSV Neuenstein I | G33: 3. | H33: SGM Fichtenberg/Rottal
A34: 4. | B34: SGM TSV Althausen-Neunkirchen/SV Wachbach | D34: 4. | E34: SGM TSV Bitzfeld/Brettachtal I | G34: 4. | H34: SGM TSV Michelbach/Bilz/SV Westheim/SV Rieden I
A35: 5. | B35: SGM Weikersheim Vorbach-Tauber (flex) | D35: 5. | E35: SGM TSV Weißbach I / Kickers Mittleres Kochertal | G35: 5. | H35: SGM TSV Sulzdorf/TSV Hessental I
A36: 6. | B36: SV Mulfingen | D36: 6. | E36: SGM TSV Zweiflingen/Ohrnberg | G36: 6. | H36: Spfr Schwäbisch Hall II
A37: 7. | B37: TV Niederstetten | D37: 7. | E37: SGM VfB Neuhütten/Wüstenrot/Neulautern | G37: 7. | H37: SSV Schwäbisch Hall I
A38: 8. | B38: VfB Bad Mergentheim | D38: 8. | E38: TSG Öhringen | G38: 8. | H38: TSV Gaildorf
A41: SL: | B41: Christian Reuter | D41: SL: | E41: Dieter Schaaf | G41: SL: | H41: Dieter Schaaf
A42: C-Junioren Qualistaffel 07 | D42: C-Junioren Qualistaffel 08 (Topf 2) | G42: C-Junioren Qualistaffel 09 (Topf 2)
A43: 1. | B43: SGM Obersontheim/Vellberg/Gründelhardt/Honhardt I | D43: 1. | E43: SGM Botenheim/Cleebronn/Eibensbach/Stockheim II (flex) | G43: 1. | H43: Aramäer Heilbronn (flex)
A44: 2. | B44: SGM Rot am See/Brettheim/Hengstfeld | D44: 2. | E44: SGM FSV Schwaigern/Oberes Leintal II | G44: 2. | H44: SC Böckingen
A45: 3. | B45: SGM SpVgg Gammesfeld/Bartenstein/Schrozberg | D45: 3. | E45: SGM Güglingen/Frauenzimmern (flex) | G45: 3. | H45: SGM Auenstein/Untergruppenbach
A46: 4. | B46: SGM SV Ingersheim/SSV Stimpfach | D46: 4. | E46: SGM Kirchhausen | G46: 4. | H46: SGM Union Heilbronn / TSN 1969 III (flex)
A47: 5. | B47: SGM TSV Gerabronn/Dünsbach/Langenburg | D47: 5. | E47: SGM MassenbachHausen (flex) | G47: 5. | H47: SV Heilbronn am Leinbach III
...

Sheet Einteilung D-Junioren
A1: Einteilung D-Junioren 2025/2026 | H1: Stand: 30.07.25
A3: SL: | B3: Alexander Ergenzinger | D3: SL: | E3: Alexander Ergenzinger | G3: SL: | H3: Alexander Ergenzinger
A4: D-Junioren Quali Bezirksstaffel 1 | D4: D-Junioren Quali Bezirksstaffel 2 | G4: D-Junioren Quali Bezirksstaffel 3
A5: 1. | B5: FSV Friedrichshaller SV I | D5: 1. | E5: SGM Oedheim/Dahenfeld I | G5: 1. | H5: SGM Ilsfeld-Abstatt-Heinriet ABI I
A6: 2. | B6: SC Amorbach I (U13) | D6: 2. | E6: SGM TSV Brettach KoBra I | G6: 2. | H6: SGM Sülzbach Sulmtal I
A7: 3. | B7: SG Bad Wimpfen I | D7: 3. | E7: Sport-Union Neckarsulm I | G7: 3. | H7: SGM Willsbach I
A8: 4. | B8: SGM Bachenau Krumme Ebene am Neckar | D8: 4. | E8: Spvgg Möckmühl I | G8: 4. | H8: Spfr Neckarwestheim I
A9: 5. | B9: SGM Union Heilbronn / TSN 1969 I | D9: 5. | E9: TSG Bretzfeld-Rappach | G9: 5. | H9: TGV Eintracht Beilstein I
A10: 6. | B10: SGM Untergriesheim H-U-T-H I | D10: 6. | E10: TSV Weinsberg I | G10: 6. | H10: TSV Untergruppenbach
A11: 7. | B11: VfR Heilbronn 96/18 III | D11: 7. | E11: VfL Eberstadt | G11: 7. | H11: TV Flein I
D12: 8. | E12: VfR Heilbronn 96/18 II
A14: SL: | B14: Dieter Schaaf | D14: SL: | E14: Dieter Schaaf | G14: SL: | H14: Michael Schmelzle
A15: D-Junioren Quali Bezirksstaffel 4 | D15: D-Junioren Quali Bezirksstaffel 5 | G15: D-Junioren Quali Bezirksstaffel 6
A16: 1. | B16: Aramäer Heilbronn | D16: 1. | E16: FC Kirchhausen | G16: 1. | H16: SGM TG Forchtenberg II / Kickers Mittleres Kochertal
A17: 2. | B17: ASV Heilbronn | D17: 2. | E17: FSV Schwaigern I | G17: 2. | H17: SGM TSV Neuenstein/Waldenburg I
A18: 3. | B18: SGM Union Heilbronn / TSN 1969 II | D18: 3. | E18: SGM Bonfeld/Fürfeld/Obergimpern I | G18: 3. | H18: SGM TSV Ohrnberg / Zweiflingen I
A19: 4. | B19: SV Heilbronn am Leinbach I | D19: 4. | E19: SGM Nordheim Unteres Zabergäu I | G19: 4. | H19: SGM TSV Pfedelbach/Jugendteam TSV I
A20: 5. | B20: TG Böckingen I | D20: 5. | E20: SGM VfL Brackenheim I | G20: 5. | H20: SGM TSV Waldbach/Brettachtal I
A21: 6. | B21: TSG Heilbronn I | D21: 6. | E21: Spfr. Lauffen I | G21: 6. | H21: TSG Öhringen I
A22: 7. | B22: TSV Talheim | D22: 7. | E22: SV Leingarten I | G22: 7. | H22: TSG Verrenberg
A23: 8. | B23: VfR Heilbronn 96/18 I
A26: SL: | B26: Michael Schmelzle | D26: SL: | E26: Andreas Leitner
A27: D-Junioren Quali Bezirksstaffel 7 | D27: D-Junioren Quali Bezirksstaffel 8
A28: 1. | B28: FV Künzelsau I | D28: 1. | E28: 1. FC Igersheim
A29: 2. | B29: SGM DJK-TSV Bieringen/Schöntal I | D29: 2. | E29: SGM FC Creglingen/Bieberehren I
A30: 3. | B30: SGM Krautheim/Mittleres Jagsttal I | D30: 3. | E30: SGM SV Wachbach/Althausen Neunkirchen
A31: 4. | B31: SGM SSV Gaisbach/TSVKupferzell/TSV Ingelfingen I | D31: 4. | E31: SGM Taubertal/Röttingen
A32: 5. | B32: SGM TG Forchtenberg I / Kickers Mittleres Kochertal | D32: 5. | E32: SGM Weikersheim Vorbach-Tauber I
A33: 6. | B33: SV Mulfingen | D33: 6. | E33: TV Niederstetten I
D34: 7. | E34: VfB Bad Mergentheim I
A37: SL: | B37: Alexander Ergenzinger | D37: SL: | E37: Alexander Ergenzinger | G37: SL: | H37: Alexander Ergenzinger
A38: D-Junioren Qualistaffel 01 | D38: D-Junioren Qualistaffel 02 | G38: D-Junioren Qualistaffel 03
A39: 1. | B39: FSV Friedrichshaller SV II | D39: 1. | E39: SGM Neudenau/Siglingen | G39: 1. | H39: SC Amorbach III
A40: 2. | B40: SC Amorbach II (U12) | D40: 2. | E40: SGM Neuenstadt II | G40: 2. | H40: Sport-Union Neckarsulm III
A41: 3. | B41: SG Bad Wimpfen II | D41: 3. | E41: SGM Oedheim/Dahenfeld II | G41: 3. | H41: SV Heilbronn am Leinbach II
A42: 4. | B42: SGM Neuenstadt I | D42: 4. | E42: Sport-Union Neckarsulm II | G42: 4. | H42: TG Böckingen II
A43: 5. | B43: SGM Union Heilbronn / TSN 1969 III | D43: 5. | E43: Spvgg Möckmühl II | G43: 5. | H43: TSG Heilbronn II
A44: 6. | B44: SGM Untergriesheim H-U-T-H II | D44: 6. | E44: SV Heilbronn am Leinbach IV | G44: 6. | H44: TV Flein III
A45: 7. | B45: TSV Erlenbach I | D45: 7. | E45: TSG Heilbronn III | G45: 7. | H45: VfL Obereisesheim I
D46: 8. | E46: VfL Obereisesheim II
...

Sheet Einteilung E-Junioren
A1: Einteilung E-Junioren 2025/2026 | H1: Stand: 11.08.25
A3: SL: | B3: Reiner Falk | D3: SL: | E3: Reiner Falk | G3: SL: | H3: Reiner Falk
A4: E-Junioren Qualistaffel 01 | D4: E-Junioren Qualistaffel 02 | G4: E-Junioren Qualistaffel 03
A5: 1. | B5: FSV Friedrichshaller SV I | D5: 1. | E5: SC Amorbach I | G5: 1. | H5: FC Obersulm I
A6: 2. | B6: SC Amorbach II | D6: 2. | E6: SGM Neudenau/Siglingen I | G6: 2. | H6: SGM Eberstadt/Gellmersbach I
A7: 3. | B7: SG Bad Wimpfen I | D7: 3. | E7: SGM TSV Hardthausen KoBra I | G7: 3. | H7: SV Sülzbach I
A8: 4. | B8: Spvgg Oedheim I | D8: 4. | E8: SGM Untergriesheim H-U-T-H I | G8: 4. | H8: TSV Erlenbach I
A9: 5. | B9: TG Offenau I | D9: 5. | E9: Sport-Union Neckarsulm I | G9: 5. | H9: TSV Talheim I
A10: 6. | B10: TSV Heinsheim | D10: 6. | E10: Spvgg Möckmühl I | G10: 6. | H10: TSV Weinsberg I
A13: SL: | B13: Reiner Falk | D13: SL: | E13: Reiner Falk | G13: SL: | H13: Reiner Falk
A14: E-Junioren Qualistaffel 04 | D14: E-Junioren Qualistaffel 05 | G14: E-Junioren Qualistaffel 06
A15: 1. | B15: SC Ilsfeld I | D15: 1. | E15: FC Kirchhausen I | G15: 1. | H15: Aramäer Heilbronn I
A16: 2. | B16: SGM Lehrensteinsfeld | D16: 2. | E16: SGM TSV Meimsheim I | G16: 2. | H16: ASV Heilbronn I
A17: 3. | B17: SGM SC Abstatt Heinriet I | D17: 3. | E17: SGM Union Heilbronn / TSN 1969 II | G17: 3. | H17: SGM Union Heilbronn / TSN 1969 I
A18: 4. | B18: Spfr Neckarwestheim I | D18: 4. | E18: Spfr Lauffen I | G18: 4. | H18: SV Heilbronn am Leinbach I
A19: 5. | B19: TGV Eintracht Beilstein I | D19: 5. | E19: SV Leingarten I | G19: 5. | H19: TG Böckingen I
A20: 6. | B20: TSV Löwenstein | D20: 6. | E20: VfR Heilbronn 96/18 | G20: 6. | H20: TSG Heilbronn I
A23: SL: | B23: Andreas Leitner | D23: SL: | E23: Andreas Leitner | G23: SL: | H23: Michael Schmelzle
A24: E-Junioren Qualistaffel 07 | D24: E-Junioren Qualistaffel 08 | G24: E-Junioren Qualistaffel 09
A25: 1. | B25: 1. FC Igersheim I | D25: 1. | E25: SGM Dörzbach/Klepsau/Hohebach I | G25: 1. | H25: FV Künzelsau I
A26: 2. | B26: SGM Röttingen/Taubertal | D26: 2. | E26: SGM SV Wachbach/TSV Althausen-Neunkirchen I | G26: 2. | H26: SGM Amrichshausen/Morsbach
A27: 3. | B27: SGM SV Edelfingen/SV Oberbalbach/DJK Unterbalbach I | D27: 3. | E27: SGM VfR Gommersdorf/TSV Krautheim I | G27: 3. | H27: SGM DJK-TSV Bieringen/Schöntal I
A28: 4. | B28: SGM Weikersheim Vorbach-Tauber I | D28: 4. | E28: SV Mulfingen | G28: 4. | H28: SGM Sindringen/Ernsbach I - Kickers Mittleres Kochertal
A29: 5. | B29: VfB Bad Mergentheim I | D29: 5. | E29: TV Niederstetten | G29: 5. | H29: SGM TSV Ingelfingen/Nagelsberg I
A32: SL: | B32: Michael Schmelzle | D32: SL: | E32: Michael Schmelzle | G32: SL: | H32: Reiner Falk
A33: E-Junioren Qualistaffel 10 | D33: E-Junioren Qualistaffel 11 | G33: E-Junioren Qualistaffel 12
A34: 1. | B34: SC Michelbach/Wald I | D34: 1. | E34: SGM TSV Bitzfeld/Brettachtal I | G34: 1. | H34: FSV Friedrichshaller SV II
A35: 2. | B35: SGM TSV Neuenstein/Waldenburg I | D35: 2. | E35: SGM TSV Pfedelbach/Jugendteam TSV I | G35: 2. | H35: SC Amorbach III
A36: 3. | B36: SGM TSV Zweiflingen/Ohrnberg I | D36: 3. | E36: TSG Bretzfeld-Rappach | G36: 3. | H36: SGM TSV Hardthausen KoBra II
A37: 4. | B37: SSV Gaisbach I | D37: 4. | E37: TSG Öhringen I | G37: 4. | H37: SGM Untergriesheim H-U-T-H II
A38: 5. | B38: TSV Kupferzell I | D38: 5. | E38: TSG Verrenberg | G38: 5. | H38: TSV Duttenberg
G39: 6. | H39: VfL Obereisesheim II
A42: SL: | B42: Reiner Falk | D42: SL: | E42: Ewald Blind | G42: SL: | H42: Ewald Blind
A43: E-Junioren Qualistaffel 13 | D43: E-Junioren Qualistaffel 14 | G43: E-Junioren Qualistaffel 15
A44: 1. | B44: FSV Friedrichshaller SV III | D44: 1. | E44: SC Dahenfeld | G44: 1. | H44: SGM Neudenau/Siglingen II
A45: 2. | B45: SC Amorbach IV | D45: 2. | E45: SG Bad Wimpfen II | G45: 2. | H45: SGM Neuenstadt I
A46: 3. | B46: SGM Gundelsheim Krumme Ebene am Neckar II | D46: 3. | E46: SGM Gundelsheim Krumme Ebene am Neckar I | G46: 3. | H46: SGM Spfr. Widdern / SV Jagsthausen I
A47: 4. | B47: SGM Neuenstadt II | D47: 4. | E47: TG Offenau II | G47: 4. | H47: SGM TSV Hardthausen KoBra III
A48: 5. | B48: Spvgg Möckmühl III | D48: 5. | E48: TSV Erlenbach II | G48: 5. | H48: Sport-Union Neckarsulm II
A49: 6. | B49: Spvgg Oedheim II | D49: 6. | E49: VfL Obereisesheim I | G49: 6. | H49: Spvgg Möckmühl II
...

Sheet Einteilung Juniorinnen
A1: Einteilung Juniorinnen 2025/2026 | H1: Stand: 30.07.25
A3: SL: | B3: Peter Parys-Allweiler | D3: SL: | E3: Josef Kohnle | G3: SL: | H3: Josef Kohnle
A4: B-Juniorinnen Qualistaffel 1 | D4: B-Juniorinnen Qualistaffel 2 | G4: B-Juniorinnen Qualistaffel 3 (Doppelrunde)
A5: 1. | B5: SGM Bonfeld/Fürfeld (9er) | D5: 1. | E5: SGM Krautheim/Westernhausen | G5: 1. | H5: FC Creglingen
A6: 2. | B6: SGM SC Ilsfeld/Beilstein/Abstatt ABI | D6: 2. | E6: SGM Rieden/Michelbach B./Tüngental | G6: 2. | H6: SGM TSV Blaufelden/Wiesenbach/Billingsbach
A7: 3. | B7: SGM Spfr Widdern | D7: 3. | E7: SGM TSV Ilshofen/TSV Dünsbach | G7: 3. | H7: SGM TSV Weikersheim/Schäftersheim/Laudenbach (9er)
A8: 4. | B8: SGM Union Heilbronn / TSN 1969 (9er) | D8: 4. | E8: SGM TSV Neuenstein/Kupferzell/Öhringen II | G8: 4. | H8: Spvgg Gammesfeld
A9: 5. | B9: Spvgg Oedheim (9er) | D9: 5. | E9: SGM TURA Untermünkheim/SpVgg Satteldorf II
A10: 6. | B10: SV Sülzbach | D10: 6. | E10: SSV Schwäbisch Hall
A11: 7. | B11: TGV Dürrenzimmern | D11: 7. | E11: TSV Langenbeutingen
A12: 8. | B12: TSV Güglingen | D12: 8. | E12: TSV Michelfeld
A15: SL: | B15: Peter Parys-Allweiler | D15: SL: | E15: Josef Kohnle | G15: SL: | H15: Josef Kohnle
A16: C-Juniorinnen Qualistaffel 1 | D16: C-Juniorinnen Qualistaffel 2 | G16: C-Juniorinnen Qualistaffel 3 (Doppelrunde)
A17: 1. | B17: SGM Bonfeld/Fürfeld (9er) | D17: 1. | E17: SGM SpVgg Satteldorf/TURA Untermünkheim I | G17: 1. | H17: FC Creglingen
A18: 2. | B18: SGM SC Ilsfeld/Abstatt/Beilstein ABI | D18: 2. | E18: SGM SV Onolzheim/TSV Crailsheim/VFB Jagstheim | G18: 2. | H18: SGM SpVgg Satteldorf/TURA Untermünkheim II
A19: 3. | B19: Spvgg Oedheim (9er) | D19: 3. | E19: SGM TSV Neuenstein/Kupferzell/Öhringen | G19: 3. | H19: SGM TSV Ilshofen/TSV Dünsbach
A20: 4. | B20: SV Sülzbach | D20: 4. | E20: Spfr DJK Bühlerzell (9er) | G20: 4. | H20: SGM TSV Weikersheim/Schäftersheim/Laudenbach (9er)
A21: 5. | B21: TSV Güglingen | D21: 5. | E21: SSV Schwäbisch Hall (9er)
A22: 6. | B22: TSV Weinsberg | D22: 6. | E22: TSV Michelfeld
D23: 7. | E23: TSV Sulzdorf
A26: SL: | B26: Peter Parys-Allweiler | D26: SL: | E26: Josef Kohnle | G26: SL: | H26: Josef Kohnle
A27: D-Juniorinnen Qualistaffel 1 | D27: D-Juniorinnen Qualistaffel 2 | G27: D-Juniorinnen Qualistaffel 3
A28: 1. | B28: FSV Friedrichshaller SV | D28: 1. | E28: SGM Neuenstein / Kupferzell / Öhringen | G28: 1. | H28: FC Creglingen
A29: 2. | B29: SGM Bonfeld/Fürfeld | D29: 2. | E29: SGM Rieden/Michelbach B./Tüngental | G29: 2. | H29: SGM Billingsbach / Blaufelden / Wiesenbach
A30: 3. | B30: SGM SC Ilsfeld/Abstatt/Beilstein ABI | D30: 3. | E30: SGM TSV Pfedelbach/Jugendteam TSV | G30: 3. | H30: SGM SV Onolzheim/TSV Crailsheim/VFB Jagstheim
A31: 4. | B31: Spvgg Oedheim I | D31: 4. | E31: Spfr DJK Bühlerzell | G31: 4. | H31: Spvgg Gammesfeld
A32: 5. | B32: Spvgg Oedheim II | D32: 5. | E32: SSV Schwäbisch Hall | G32: 5. | H32: SpVgg Gröningen-Satteldorf
A33: 6. | B33: SV Sülzbach | D33: 6. | E33: TSV Michelfeld | G33: 6. | H33: TSV Ilshofen
A34: 7. | B34: TSV Weinsberg | D34: 7. | E34: TURA Untermünkheim

Sheet Tabelle1
C1: A | D1: B | E1: C | F1: D | G1: E | H1: Mädchen
A2: Reiner Falk | B2: =COUNTIF('Einteilung A-Junioren'!A:H,A2)+COUNTIF('Einteilung B-Junioren'!A:H,A2)+COUNTIF('Einteilung C-Junioren'!A:H,A2)+COUNTIF('Einteilung D-Junioren'!A:H,A2)+COUNTIF('Einteilung E-Junioren'!A:H,A2)+COUNTIF('Einteilung Juniorinnen'!A:H,A2) -> 11 | C2: =COUNTIF('Einteilung A-Junioren'!A:H,A2) -> 3 | D2: =COUNTIF('Einteilung B-Junioren'!A:H,A2) -> 0 | E2: =COUNTIF('Einteilung C-Junioren'!A:H,A2) -> 0 | F2: =COUNTIF('Einteilung D-Junioren'!A:H,A2) -> 0 | G2: =COUNTIF('Einteilung E-Junioren'!A:H,A2) -> 8 | H2: =COUNTIF('Einteilung Juniorinnen'!A:H,A2) -> 0
A3: Bernhard Nied | B3: =COUNTIF('Einteilung A-Junioren'!A:H,A3)+COUNTIF('Einteilung B-Junioren'!A:H,A3)+COUNTIF('Einteilung C-Junioren'!A:H,A3)+COUNTIF('Einteilung D-Junioren'!A:H,A3)+COUNTIF('Einteilung E-Junioren'!A:H,A3)+COUNTIF('Einteilung Juniorinnen'!A:H,A3) -> 5 | C3: =COUNTIF('Einteilung A-Junioren'!A:H,A3) -> 0 | D3: =COUNTIF('Einteilung B-Junioren'!A:H,A3) -> 5 | E3: =COUNTIF('Einteilung C-Junioren'!A:H,A3) -> 0 | F3: =COUNTIF('Einteilung D-Junioren'!A:H,A3) -> 0 | G3: =COUNTIF('Einteilung E-Junioren'!A:H,A3) -> 0 | H3: =COUNTIF('Einteilung Juniorinnen'!A:H,A3) -> 0
A4: Peter Parys-Allweiler | B4: =COUNTIF('Einteilung A-Junioren'!A:H,A4)+COUNTIF('Einteilung B-Junioren'!A:H,A4)+COUNTIF('Einteilung C-Junioren'!A:H,A4)+COUNTIF('Einteilung D-Junioren'!A:H,A4)+COUNTIF('Einteilung E-Junioren'!A:H,A4)+COUNTIF('Einteilung Juniorinnen'!A:H,A4) -> 6 | C4: =COUNTIF('Einteilung A-Junioren'!A:H,A4) -> 0 | D4: =COUNTIF('Einteilung B-Junioren'!A:H,A4) -> 0 | E4: =COUNTIF('Einteilung C-Junioren'!A:H,A4) -> 3 | F4: =COUNTIF('Einteilung D-Junioren'!A:H,A4) -> 0 | G4: =COUNTIF('Einteilung E-Junioren'!A:H,A4) -> 0 | H4: =COUNTIF('Einteilung Juniorinnen'!A:H,A4) -> 3
A5: Dieter Schaaf | B5: =COUNTIF('Einteilung A-Junioren'!A:H,A5)+COUNTIF('Einteilung B-Junioren'!A:H,A5)+COUNTIF('Einteilung C-Junioren'!A:H,A5)+COUNTIF('Einteilung D-Junioren'!A:H,A5)+COUNTIF('Einteilung E-Junioren'!A:H,A5)+COUNTIF('Einteilung Juniorinnen'!A:H,A5) -> 8 | C5: =COUNTIF('Einteilung A-Junioren'!A:H,A5) -> 0 | D5: =COUNTIF('Einteilung B-Junioren'!A:H,A5) -> 0 | E5: =COUNTIF('Einteilung C-Junioren'!A:H,A5) -> 3 | F5: =COUNTIF('Einteilung D-Junioren'!A:H,A5) -> 5 | G5: =COUNTIF('Einteilung E-Junioren'!A:H,A5) -> 0 | H5: =COUNTIF('Einteilung Juniorinnen'!A:H,A5) -> 0
A6: Alexander Ergenzinger | B6: =COUNTIF('Einteilung A-Junioren'!A:H,A6)+COUNTIF('Einteilung B-Junioren'!A:H,A6)+COUNTIF('Einteilung C-Junioren'!A:H,A6)+COUNTIF('Einteilung D-Junioren'!A:H,A6)+COUNTIF('Einteilung E-Junioren'!A:H,A6)+COUNTIF('Einteilung Juniorinnen'!A:H,A6) -> 7 | C6: =COUNTIF('Einteilung A-Junioren'!A:H,A6) -> 0 | D6: =COUNTIF('Einteilung B-Junioren'!A:H,A6) -> 0 | E6: =COUNTIF('Einteilung C-Junioren'!A:H,A6) -> 0 | F6: =COUNTIF('Einteilung D-Junioren'!A:H,A6) -> 7 | G6: =COUNTIF('Einteilung E-Junioren'!A:H,A6) -> 0 | H6: =COUNTIF('Einteilung Juniorinnen'!A:H,A6) -> 0
A7: Ewald Blind | B7: =COUNTIF('Einteilung A-Junioren'!A:H,A7)+COUNTIF('Einteilung B-Junioren'!A:H,A7)+COUNTIF('Einteilung C-Junioren'!A:H,A7)+COUNTIF('Einteilung D-Junioren'!A:H,A7)+COUNTIF('Einteilung E-Junioren'!A:H,A7)+COUNTIF('Einteilung Juniorinnen'!A:H,A7) -> 12 | C7: =COUNTIF('Einteilung A-Junioren'!A:H,A7) -> 0 | D7: =COUNTIF('Einteilung B-Junioren'!A:H,A7) -> 0 | E7: =COUNTIF('Einteilung C-Junioren'!A:H,A7) -> 0 | F7: =COUNTIF('Einteilung D-Junioren'!A:H,A7) -> 0 | G7: =COUNTIF('Einteilung E-Junioren'!A:H,A7) -> 12 | H7: =COUNTIF('Einteilung Juniorinnen'!A:H,A7) -> 0
A8: Karl Ruck | B8: =COUNTIF('Einteilung A-Junioren'!A:H,A8)+COUNTIF('Einteilung B-Junioren'!A:H,A8)+COUNTIF('Einteilung C-Junioren'!A:H,A8)+COUNTIF('Einteilung D-Junioren'!A:H,A8)+COUNTIF('Einteilung E-Junioren'!A:H,A8)+COUNTIF('Einteilung Juniorinnen'!A:H,A8) -> 4 | C8: =COUNTIF('Einteilung A-Junioren'!A:H,A8) -> 4 | D8: =COUNTIF('Einteilung B-Junioren'!A:H,A8) -> 0 | E8: =COUNTIF('Einteilung C-Junioren'!A:H,A8) -> 0 | F8: =COUNTIF('Einteilung D-Junioren'!A:H,A8) -> 0 | G8: =COUNTIF('Einteilung E-Junioren'!A:H,A8) -> 0 | H8: =COUNTIF('Einteilung Juniorinnen'!A:H,A8) -> 0
A9: Franz Schmitt | B9: =COUNTIF('Einteilung A-Junioren'!A:H,A9)+COUNTIF('Einteilung B-Junioren'!A:H,A9)+COUNTIF('Einteilung C-Junioren'!A:H,A9)+COUNTIF('Einteilung D-Junioren'!A:H,A9)+COUNTIF('Einteilung E-Junioren'!A:H,A9)+COUNTIF('Einteilung Juniorinnen'!A:H,A9) -> 5 | C9: =COUNTIF('Einteilung A-Junioren'!A:H,A9) -> 0 | D9: =COUNTIF('Einteilung B-Junioren'!A:H,A9) -> 4 | E9: =COUNTIF('Einteilung C-Junioren'!A:H,A9) -> 1 | F9: =COUNTIF('Einteilung D-Junioren'!A:H,A9) -> 0 | G9: =COUNTIF('Einteilung E-Junioren'!A:H,A9) -> 0 | H9: =COUNTIF('Einteilung Juniorinnen'!A:H,A9) -> 0
A10: Andreas Leitner | B10: =COUNTIF('Einteilung A-Junioren'!A:H,A10)+COUNTIF('Einteilung B-Junioren'!A:H,A10)+COUNTIF('Einteilung C-Junioren'!A:H,A10)+COUNTIF('Einteilung D-Junioren'!A:H,A10)+COUNTIF('Einteilung E-Junioren'!A:H,A10)+COUNTIF('Einteilung Juniorinnen'!A:H,A10) -> 10 | C10: =COUNTIF('Einteilung A-Junioren'!A:H,A10) -> 0 | D10: =COUNTIF('Einteilung B-Junioren'!A:H,A10) -> 0 | E10: =COUNTIF('Einteilung C-Junioren'!A:H,A10) -> 4 | F10: =COUNTIF('Einteilung D-Junioren'!A:H,A10) -> 2 | G10: =COUNTIF('Einteilung E-Junioren'!A:H,A10) -> 4 | H10: =COUNTIF('Einteilung Juniorinnen'!A:H,A10) -> 0
A11: Michael Schmelzle | B11: =COUNTIF('Einteilung A-Junioren'!A:H,A11)+COUNTIF('Einteilung B-Junioren'!A:H,A11)+COUNTIF('Einteilung C-Junioren'!A:H,A11)+COUNTIF('Einteilung D-Junioren'!A:H,A11)+COUNTIF('Einteilung E-Junioren'!A:H,A11)+COUNTIF('Einteilung Juniorinnen'!A:H,A11) -> 11 | C11: =COUNTIF('Einteilung A-Junioren'!A:H,A11) -> 0 | D11: =COUNTIF('Einteilung B-Junioren'!A:H,A11) -> 0 | E11: =COUNTIF('Einteilung C-Junioren'!A:H,A11) -> 0 | F11: =COUNTIF('Einteilung D-Junioren'!A:H,A11) -> 5 | G11: =COUNTIF('Einteilung E-Junioren'!A:H,A11) -> 6 | H11: =COUNTIF('Einteilung Juniorinnen'!A:H,A11) -> 0
A12: Christian Reuter | B12: =COUNTIF('Einteilung A-Junioren'!A:H,A12)+COUNTIF('Einteilung B-Junioren'!A:H,A12)+COUNTIF('Einteilung C-Junioren'!A:H,A12)+COUNTIF('Einteilung D-Junioren'!A:H,A12)+COUNTIF('Einteilung E-Junioren'!A:H,A12)+COUNTIF('Einteilung Juniorinnen'!A:H,A12) -> 3 | C12: =COUNTIF('Einteilung A-Junioren'!A:H,A12) -> 0 | D12: =COUNTIF('Einteilung B-Junioren'!A:H,A12) -> 1 | E12: =COUNTIF('Einteilung C-Junioren'!A:H,A12) -> 2 | F12: =COUNTIF('Einteilung D-Junioren'!A:H,A12) -> 0 | G12: =COUNTIF('Einteilung E-Junioren'!A:H,A12) -> 0 | H12: =COUNTIF('Einteilung Juniorinnen'!A:H,A12) -> 0
A13: Josef Kohnle | B13: =COUNTIF('Einteilung A-Junioren'!A:H,A13)+COUNTIF('Einteilung B-Junioren'!A:H,A13)+COUNTIF('Einteilung C-Junioren'!A:H,A13)+COUNTIF('Einteilung D-Junioren'!A:H,A13)+COUNTIF('Einteilung E-Junioren'!A:H,A13)+COUNTIF('Einteilung Juniorinnen'!A:H,A13) -> 6 | C13: =COUNTIF('Einteilung A-Junioren'!A:H,A13) -> 0 | D13: =COUNTIF('Einteilung B-Junioren'!A:H,A13) -> 0 | E13: =COUNTIF('Einteilung C-Junioren'!A:H,A13) -> 0 | F13: =COUNTIF('Einteilung D-Junioren'!A:H,A13) -> 0 | G13: =COUNTIF('Einteilung E-Junioren'!A:H,A13) -> 0 | H13: =COUNTIF('Einteilung Juniorinnen'!A:H,A13) -> 6
B14: =SUM(B2:B13) -> 88 | C14: =SUM(C2:C13) -> 7 | D14: =SUM(D2:D13) -> 10 | E14: =SUM(E2:E13) -> 13 | F14: =SUM(F2:F13) -> 19 | G14: =SUM(G2:G13) -> 30 | H14: =SUM(H2:H13) -> 9
C16: 7 | D16: 10 | E16: 12 | F16: 18 | G16: 30 | H16: 9
