Workbook

Sheet A-Junioren
A1: Vorschlag Einteilung Rückrunde A-Junioren 2025/2026 | L1: Stand: 31.12.25 | Q1: keine Teilnahme Leistungsstaffel (Verzicht / flex) | S1: LS | T1: =COUNTIF($T$5:T$52,S1) -> 10 | X1: LS | Y1: =COUNTIF($Y$5:$Y$52,X1) -> 10
Q2: Rückzug | S2: KS | T2: =COUNTIF($T$5:T$52,S2) -> 14 | X2: KS | Y2: =COUNTIF($Y$5:$Y$52,X2) -> 11
A3: SL: | B3: Reiner Falk | F3: SL: | G3: Karl Ruck
A4: A-Junioren Leistungsstaffel 1 | C4: Punkte | D4: Q | F4: A-Junioren Leistungsstaffel 2 | H4: Punkte | I4: Q | Q4: Unterland | R4: Punkte | S4: Q | V4: Hohenlohe | W4: Punkte | X4: Q
A5: 1. | B5: SGM SC Abstatt/Beilstein/Ilsfeld/Heinriet ABI | C5: 22 | D5: 2.75 | F5: 1. | G5: SC Michelbach/Wald | H5: 15 | I5: 2.5 | P5: 1. | Q5: SGM SC Abstatt/Beilstein/Ilsfeld/Heinriet ABI | R5: 22 | S5: 2.75 | T5: LS | U5: 1. | V5: SC Michelbach/Wald | W5: 15 | X5: 2.5 | Y5: LS
A6: 2. | B6: SGM Cleebronn/Botenheim/Eibensbach/Stockheim | C6: 19 | D6: 2.375 | F6: 2. | G6: SGM TSV Kupferzell/Gaisbach/Ingelfingen | H6: 12 | I6: 2 | P6: 2. | Q6: SGM Cleebronn/Botenheim/Eibensbach/Stockheim | R6: 19 | S6: 2.375 | T6: LS | U6: 2. | V6: SGM TSV Kupferzell/Gaisbach/Ingelfingen | W6: 12 | X6: 2 | Y6: LS
A7: 3. | B7: SV Leingarten | C7: 16 | D7: 2 | F7: 3. | G7: SC Steinbach | H7: 12 | I7: 2 | P7: 3. | Q7: SV Leingarten | R7: 16 | S7: 2 | T7: LS | U7: 3. | V7: SC Steinbach | W7: 12 | X7: 2 | Y7: LS
A8: 4. | B8: SGM Dürrenzimmern Unteres Zabergäu | C8: 12 | D8: 1.5 | F8: 4. | G8: SGM SSV Schwäbisch Hall/Tura Untermünkheim | H8: 12 | I8: 2 | P8: 4. | Q8: SGM Dürrenzimmern Unteres Zabergäu | R8: 12 | S8: 1.5 | T8: LS | U8: 4. | V8: SGM SSV Schwäbisch Hall/Tura Untermünkheim | W8: 12 | X8: 2 | Y8: LS
A9: 5. | B9: SGM Kirchhausen | C9: 8 | D9: 1 | F9: 5. | G9: SGM Vellberg/Obersontheim/Gründelh.-Operspeltach/Honhardt | H9: 16 | I9: 2.2857143 | P9: 5. | Q9: SGM Lehrensteinsfeld (flex) | R9: 9 | S9: 1.125 | T9: KS | U9: 5. | V9: SGM TSV Schwabbach/Brettachtal | W9: 6 | X9: 1 | Y9: KS
A10: 6. | B10: SG Bad Wimpfen | C10: 16 | D10: 2.6666667 | F10: 6. | G10: SGM Sulzdorf/Hessental | H10: 16 | I10: 2.2857143 | P10: 6. | Q10: SGM Kirchhausen | R10: 8 | S10: 1 | T10: LS | U10: 6. | V10: SGM VfB Neuhütten/Wüstenrot/Neulautern | W10: 6 | X10: 1 | Y10: KS
A11: 7. | B11: SGM Höchstberg H-U-T-H I | C11: 12 | D11: 2 | F11: 7. | G11: TSV Crailsheim | H11: 16 | I11: 2.2857143 | P11: 7. | Q11: TSV Weinsberg | R11: 6 | S11: 0.75 | T11: KS | U11: 7. | V11: SGM SV Berlichingen/Schöntal/Mittleres Kochertal | W11: 0 | X11: 0
A12: 8. | B12: SC Amorbach | C12: 12 | D12: 2 | F12: 8. | G12: SGM VfB Bad Mergentheim /1. FC Igersheim | H12: 18 | I12: 2.5714286 | P12: 8. | Q12: TSV Untergruppenbach | R12: 5 | S12: 0.625 | T12: KS | U12: 8. | V12: SGM VfR Gommersdorf/Mittleres Jagsttal II (flex) zg. | W12: 0
A13: 9. | B13: SGM Neuenstadt Kochertal | C13: 7 | D13: 1.1666667 | F13: 9. | G13: SGM Hengstfeld/Rot am See/Brettheim | H13: 15 | I13: 2.1428571 | P13: 9. | Q13: SGM TSV Meimsheim Neckar/Zabergäu | R13: 5 | S13: 0.625 | T13: KS
A14: 10. | B14: SGM Obergriesheim Krumme Ebene am Neckar | C14: 7 | D14: 1.1666667 | F14: 10. | G14: SGM Dünsbach/Blaufelden/Gerabronn/Billingsbach | H14: 13 | I14: 1.8571429 | U14: 1. | V14: SGM Vellberg/Obersontheim/Gründelh.-Operspeltach/Honhardt | W14: 16 | X14: 2.2857143 | Y14: LS
P15: 1. | Q15: SG Bad Wimpfen | R15: 16 | S15: 2.6666667 | T15: LS | U15: 2. | V15: SGM Sulzdorf/Hessental | W15: 16 | X15: 2.2857143 | Y15: LS
P16: 2. | Q16: SGM Höchstberg H-U-T-H I | R16: 12 | S16: 2 | T16: LS | U16: 3. | V16: TSV Crailsheim | W16: 16 | X16: 2.2857143 | Y16: LS
A17: SL: | B17: Reiner Falk | F17: SL: | G17: Reiner Falk | P17: 3. | Q17: SC Amorbach | R17: 12 | S17: 2 | T17: LS | U17: 4. | V17: SGM Bühlerzell/Bühlertann | W17: 9 | X17: 1.2857143 | Y17: KS
A18: A-Junioren Kreisstaffel 1 (Doppelrunde) | C18: Punkte | D18: Q | F18: A-Junioren Kreisstaffel 2 | H18: Punkte | I18: Q | P18: 4. | Q18: SGM Neuenstadt Kochertal | R18: 7 | S18: 1.1666667 | T18: LS | U18: 5. | V18: TSV Gaildorf (flex) | W18: 9 | X18: 1.2857143 | Y18: KS
A19: 1. | B19: SGM Lehrensteinsfeld (flex) | C19: 9 | D19: 1.125 | F19: 1. | G19: SGM TSV Niederhofen/Oberes Leintal (flex) | H19: 18 | I19: 2.25 | P19: 5. | Q19: SGM Obergriesheim Krumme Ebene am Neckar | R19: 7 | S19: 1.1666667 | T19: LS | U19: 6. | V19: SGM Eutendorf/Ottendorf | W19: 9 | X19: 1.2857143 | Y19: KS
A20: 2. | B20: TSV Weinsberg | C20: 6 | D20: 0.75 | F20: 2. | G20: SGM Ellhofen Sulmtal (flex) | H20: 17 | I20: 2.125 | P20: 6. | Q20: Aramäer Heilbronn | R20: 7 | S20: 1.1666667 | U20: 7. | V20: SGM Oberrot/Rottal (flex) | W20: 6 | X20: 0.85714286 | Y20: KS
A21: 3. | B21: TSV Untergruppenbach | C21: 5 | D21: 0.625 | F21: 3. | G21: SGM Oberes Zabergäu/Mühlbach/Sulzfeld | H21: 15 | I21: 1.875 | P21: 7. | Q21: TG Böckingen | R21: 0 | S21: 0 | T21: KS | U21: 8. | V21: SGM VfR Altenmünster/SV Onolzheim (flex) | W21: 0 | X21: 0 | Y21: KS
A22: 4. | B22: SGM TSV Meimsheim Neckar/Zabergäu | C22: 5 | D22: 0.625 | F22: 4. | G22: SSV Auenstein | H22: 13 | I22: 1.625 | P22: 8. | Q22: TSG Heilbronn zg. | R22: 0
A23: 5. | B23: TG Böckingen | C23: 0 | D23: 0 | F23: 5. | G23: SGM Neckarwestheim/Talheim II | H23: 12 | I23: 1.5 | U23: 1. | V23: SGM VfB Bad Mergentheim /1. FC Igersheim | W23: 18 | X23: 2.5714286 | Y23: LS
A24: 6. | B24: SV Heilbronn am Leinbach | C24: 16 | D24: 2 | F24: 6. | G24: SGM Höchstberg H-U-T-H II (flex) | H24: 6 | I24: 0.75 | P24: 1. | Q24: SGM TSV Niederhofen/Oberes Leintal (flex) | R24: 18 | S24: 2.25 | T24: KS | U24: 2. | V24: SGM Weikersheim Vorbach-Tauber | W24: 15 | X24: 2.1428571 | Y24: KS
F25: 7. | G25: SC Böckingen (flex) | H25: 4 | I25: 0.5 | P25: 2. | Q25: SGM Ellhofen Sulmtal (flex) | R25: 17 | S25: 2.125 | T25: KS | U25: 3. | V25: SGM Hengstfeld/Rot am See/Brettheim | W25: 15 | X25: 2.1428571 | Y25: LS
F26: 8. | G26: SGM Bonfeld/Fürfeld/Obergimpern (flex) | H26: 4 | I26: 0.5 | P26: 3. | Q26: SV Heilbronn am Leinbach (flex) | R26: 16 | S26: 2 | T26: KS | U26: 4. | V26: SGM Dünsbach/Blaufelden/Gerabronn/Billingsbach | W26: 13 | X26: 1.8571429 | Y26: LS
P27: 4. | Q27: SGM Oberes Zabergäu/Mühlbach/Sulzfeld | R27: 15 | S27: 1.875 | T27: KS | U27: 5. | V27: SGM TSV Schrozberg / Gammesfeld / Bartenstein | W27: 10 | X27: 1.4285714 | Y27: KS
P28: 5. | Q28: SSV Auenstein | R28: 13 | S28: 1.625 | T28: KS | U28: 6. | V28: TV Niederstetten (flex) | W28: 6 | X28: 0.85714286 | Y28: KS
A29: SL: | B29: Karl Ruck | F29: SL: | G29: Karl Ruck | P29: 6. | Q29: SGM Neckarwestheim/Talheim II | R29: 12 | S29: 1.5 | T29: KS | U29: 7. | V29: TSG Kirchberg/Jagst | W29: 5 | X29: 0.71428571
A30: A-Junioren Kreisstaffel 3 (Doppelrunde) | C30: Punkte | D30: Q | F30: A-Junioren Kreisstaffel 4 (Doppelrunde) | H30: Punkte | I30: Q | P30: 7. | Q30: SGM Höchstberg H-U-T-H II (flex) | R30: 6 | S30: 0.75 | T30: KS | U30: 8. | V30: SGM FC Creglingen/Oberes Taubertal | W30: 0 | X30: 0 | Y30: KS
A31: 1. | B31: SGM TSV Schwabbach/Brettachtal | C31: 6 | D31: 1 | F31: 1. | G31: SGM VfR Altenmünster/SV Onolzheim (flex) | H31: 0 | I31: 0 | P31: 8. | Q31: SC Böckingen (flex) | R31: 4 | S31: 0.5 | T31: KS
A32: 2. | B32: SGM VfB Neuhütten/Wüstenrot/Neulautern (flex) | C32: 6 | D32: 1 | F32: 2. | G32: SGM Weikersheim Vorbach-Tauber | H32: 15 | I32: 2.1428571 | P32: 9. | Q32: SGM Bonfeld/Fürfeld/Obergimpern (flex) | R32: 4 | S32: 0.5 | T32: KS
A33: 3. | B33: SGM Bühlerzell/Bühlertann (flex) | C33: 9 | D33: 1.2857143 | F33: 3. | G33: SGM TSV Schrozberg / Gammesfeld / Bartenstein | H33: 10 | I33: 1.4285714
A34: 4. | B34: TSV Gaildorf (flex) | C34: 9 | D34: 1.2857143 | F34: 4. | G34: TV Niederstetten (flex) | H34: 6 | I34: 0.85714286
A35: 5. | B35: SGM Eutendorf/Ottendorf | C35: 9 | D35: 1.2857143 | F35: 5. | G35: SGM FC Creglingen/Oberes Taubertal | H35: 0 | I35: 0
A36: 6. | B36: SGM Oberrot/Rottal (flex) | C36: 6 | D36: 0.85714286

Sheet B-Junioren
A1: Vorschlag Einteilung Rückrunde B-Junioren 2025/2026 | L1: Stand: 31.12.25 | Q1: keine Teilnahme Leistungsstaffel (Verzicht / flex / rückv. Spieler) | S1: LS | T1: =COUNTIF($T$6:T$52,S1) -> 10 | X1: LS | Y1: =COUNTIF($Y$6:$Y$52,X1) -> 10
Q2: Rückzug | S2: KS | T2: =COUNTIF($T$6:T$52,S2) -> 21 | X2: KS | Y2: =COUNTIF($Y$6:$Y$52,X2) -> 26
A3: SL: | B3: Bernhard Nied | F3: SL: | G3: Franz Schmitt | Q3: Änderung Mannschaftsstärke zur Rückrunde
A4: B-Junioren Leistungsstaffel 1 | C4: Punkte | D4: Q | F4: B-Junioren Leistungsstaffel 2 | H4: Punkte | I4: Q
A5: 1. | B5: SGM Oedheim Kochertal I | C5: 19 | D5: 2.375 | F5: 1. | G5: VfB Bad Mergentheim | H5: 21 | I5: 3 | Q5: Unterland | R5: Punkte | S5: Q | V5: Hohenlohe | W5: Punkte | X5: Q
A6: 2. | B6: SV Heilbronn am Leinbach I | C6: 19 | D6: 2.375 | F6: 2. | G6: 1. FC Igersheim | H6: 18 | I6: 2.5714286 | P6: 1. | Q6: SGM Oedheim Kochertal I | R6: 19 | S6: 2.375 | T6: LS | U6: 1. | V6: VfB Bad Mergentheim | W6: 21 | X6: 3 | Y6: LS
A7: 3. | B7: SG Bad Wimpfen I | C7: 17 | D7: 2.125 | F7: 3. | G7: SGM Hengstfeld/Rot am See/Brettheim | H7: 15 | I7: 2.1428571 | P7: 2. | Q7: SV Heilbronn am Leinbach I | R7: 19 | S7: 2.375 | T7: LS | U7: 2. | V7: 1. FC Igersheim | W7: 18 | X7: 2.5714286 | Y7: LS
A8: 4. | B8: FSV Friedrichshaller SV | C8: 7 | D8: 0.875 | F8: 4. | G8: SGM TSV Ingelfingen/Gaisbach/Kupferzell | H8: 16 | I8: 2.2857143 | P8: 3. | Q8: SG Bad Wimpfen I | R8: 17 | S8: 2.125 | T8: LS | U8: 3. | V8: SGM Hengstfeld/Rot am See/Brettheim | W8: 15 | X8: 2.1428571 | Y8: LS
A9: 5. | B9: SV Schluchtern U17 | C9: 24 | D9: 3 | F9: 5. | G9: SGM SV Westernhausen/ Schöntal | H9: 15 | I9: 2.1428571 | P9: 4. | Q9: SGM TSV Neudenau Unteres Jagsttal I | R9: 17 | S9: 2.4285714 | T9: KS | U9: 4. | V9: SGM SpVgg Gammesfeld/Schrozberg/Bartenstein | W9: 10 | X9: 1.4285714 | Y9: KS
A10: 6. | B10: SGM TGV Eintracht Beilstein/Abstatt/Ilsfeld/Heinriet ABI | C10: 19 | D10: 2.375 | F10: 6. | G10: SGM VfL Mainhardt/Juniorteam MMB I | H10: 18 | I10: 3 | P10: 5. | Q10: SGM VfL Eberstadt EbErG | R10: 10 | S10: 1.25 | T10: KS | U10: 5. | V10: TV Niederstetten (flex) | W10: 9 | X10: 1.2857143 | Y10: KS
A11: 7. | B11: SGM SG Stetten-Kleingartach/Oberes Leintal I | C11: 16 | D11: 2 | F11: 7. | G11: SGM TSV Pfedelbach/Jugendteam TSV I | H11: 15 | I11: 2.5 | P11: 6. | Q11: FSV Friedrichshaller SV | R11: 7 | S11: 0.875 | T11: LS | U11: 6. | V11: SGM FC Creglingen/Bieberehren/Röttingen/Taubertal (flex) | W11: 4 | X11: 0.66666667 | Y11: KS
A12: 8. | B12: SGM Hausen Unteres Zabergäu I | C12: 13 | D12: 1.625 | F12: 8. | G12: SGM VfR Altenmünster/SV Onolzheim | H12: 18 | I12: 2.5714286 | P12: 7. | Q12: TSG Heilbronn | R12: 6 | S12: 0.75 | T12: KS | U12: 7. | V12: SGM SV Wachbach/TSV Althausen-Neunkirchen (flex) | W12: 3 | X12: 0.42857143 | Y12: KS
A13: 9. | B13: SGM Spfr. Lauffen Neckar/Zabergäu | C13: 13 | D13: 1.625 | F13: 9. | G13: SGM FC Langenburg/Blaufelden/Braunsbach/Dünsbach I | H13: 15 | I13: 2.1428571 | P13: 8. | Q13: TG Böckingen | R13: 6 | S13: 0.75 | T13: KS | U13: 8. | V13: SGM Weikersheim Vorbach-Tauber | W13: 0 | X13: 0 | Y13: KS
A14: 10. | B14: SV Leingarten | C14: 6 | D14: 0.75 | F14: 10. | G14: SV Tüngental | H14: 15 | I14: 2.1428571 | P14: 9. | Q14: VfL Obereisesheim | R14: 0 | S14: 0 | T14: KS
P15: 10. | Q15: SC Amorbach zg. | R15: 0 | U15: 1. | V15: SGM TSV Ingelfingen/Gaisbach/Kupferzell | W15: 16 | X15: 2.2857143 | Y15: LS
U16: 2. | V16: SGM TSV Neuenstein/Waldenburg | W16: 16 | X16: 2.2857143 | Y16: KS
A17: SL: | B17: Bernhard Nied | F17: SL: | G17: Bernhard Nied | K17: SL: | L17: Franz Schmitt | P17: 1. | Q17: SV Schluchtern U17 | R17: 24 | S17: 3 | T17: LS | U17: 3. | V17: SGM SV Westernhausen/ Schöntal | W17: 15 | X17: 2.1428571 | Y17: LS
A18: B-Junioren Kreisstaffel 1 | C18: Punkte | D18: Q | F18: B-Junioren Kreisstaffel 2 | H18: Punkte | I18: Q | K18: B-Junioren Kreisstaffel 3 | M18: Punkte | N18: Q | P18: 2. | Q18: SGM TGV Eintracht Beilstein/Abstatt/Ilsfeld/Heinriet ABI | R18: 19 | S18: 2.375 | T18: LS | U18: 4. | V18: SC Michelbach/Wald | W18: 13 | X18: 1.8571429 | Y18: KS
A19: 1. | B19: SGM TSV Neudenau Unteres Jagsttal I | C19: 17 | D19: 2.4285714 | F19: 1. | G19: SGM Obersulm (flex) | H19: 16 | I19: 2.2857143 | K19: 1. | L19: SGM TSV Neuenstein/Waldenburg | M19: 16 | N19: =VLOOKUP(L19,$V:$X,3,0) -> 2.2857143 | P19: 3. | Q19: SGM SG Stetten-Kleingartach/Oberes Leintal I | R19: 16 | S19: 2 | T19: LS | U19: 5. | V19: SGM TSV Niedernhall I / Kickers Mittleres Kochertal | W19: 13 | X19: 1.8571429 | Y19: KS
A20: 2. | B20: SGM VfL Eberstadt EbErG | C20: 10 | D20: 1.25 | F20: 2. | G20: SSV Auenstein | H20: 15 | I20: 2.1428571 | K20: 2. | L20: SC Michelbach/Wald | M20: 13 | N20: =VLOOKUP(L20,$V:$X,3,0) -> 1.8571429 | P20: 4. | Q20: SGM Hausen Unteres Zabergäu I | R20: 13 | S20: 1.625 | T20: LS | U20: 6. | V20: SGM TSV Pfedelbach/Jugendteam TSV II | W20: 6 | X20: 0.85714286 | Y20: KS
A21: 3. | B21: TSG Heilbronn | C21: 6 | D21: 0.75 | F21: 3. | G21: SGM Eibensbach/Cleebronn/Botenheim/Stockheim II | H21: 14 | I21: 2 | K21: 3. | L21: SGM TSV Niedernhall I / Kickers Mittleres Kochertal | M21: 13 | N21: =VLOOKUP(L21,$V:$X,3,0) -> 1.8571429 | P21: 5. | Q21: SGM Spfr. Lauffen Neckar/Zabergäu | R21: 13 | S21: 1.625 | T21: LS | U21: 7. | V21: SGM TSV Schwabbach/Brettachtal (flex) | W21: 1 | X21: 0.14285714
A22: 4. | B22: TG Böckingen | C22: 6 | D22: 0.75 | F22: 4. | G22: SC Böckingen | H22: 10 | I22: 1.4285714 | K22: 4. | L22: SGM SV Westheim / TSV Michelbach-Bilz / SV Rieden | M22: 9 | N22: =VLOOKUP(L22,$V:$X,3,0) -> 1.8 | P22: 6. | Q22: SV Leingarten | R22: 6 | S22: 0.75 | T22: LS | U22: 8. | V22: SGM TSV Ohrnberg / Zweiflingen | W22: 1 | X22: 0.14285714 | Y22: KS
A23: 5. | B23: VfL Obereisesheim | C23: 0 | D23: 0 | F23: 5. | G23: SGM SG Stetten-Kleingartach/Oberes Leintal II (flex) | H23: 9 | I23: 1.2857143 | K23: 5. | L23: SGM FC Langenburg/Blaufelden/Braunsbach/Dünsbach II | M23: 12 | N23: =VLOOKUP(L23,$V:$X,3,0) -> 2.4 | P23: 7. | Q23: Spfr Neckarwestheim II | R23: 6 | S23: 0.75 | T23: KS
A24: 6. | B24: Spfr Neckarwestheim II | C24: 6 | D24: 0.75 | F24: 6. | G24: SV Heilbronn am Leinbach II (flex) | H24: 7 | I24: 1 | K24: 6. | L24: SGM SpVgg Gammesfeld/Schrozberg/Bartenstein | M24: 10 | N24: =VLOOKUP(L24,$V:$X,3,0) -> 1.4285714 | P24: 8. | Q24: SGM Ellhofen Sulmtal | R24: 5 | S24: 0.625 | T24: KS | U24: 1. | V24: SGM VfL Mainhardt/Juniorteam MMB I | W24: 18 | X24: 3 | Y24: LS
A25: 7. | B25: SGM Ellhofen Sulmtal | C25: 5 | D25: 0.625 | F25: 7. | G25: TSV Talheim (flex) | H25: 1 | I25: 0.14285714 | K25: 7. | L25: SGM Gründelhardt-Oberspeltach/Honhardt/Obersontheim/Vellberg | M25: 15 | N25: =VLOOKUP(L25,$V:$X,3,0) -> 2.1428571 | P25: 9. | Q25: TSV Weinsberg | R25: 2 | S25: 0.25 | T25: KS | U25: 2. | V25: SGM TSV Pfedelbach/Jugendteam TSV I | W25: 15 | X25: 2.5 | Y25: LS
A26: 8. | B26: TSV Weinsberg | C26: 2 | D26: 0.25 | F26: 8. | G26: SGM TSV Neudenau Unteres Jagsttal II (flex) | H26: 9 | I26: 1.125 | K26: 8. | L26: SGM SV Ingersheim/SSV Stimpfach | M26: 10 | N26: =VLOOKUP(L26,$V:$X,3,0) -> 1.4285714 | U26: 3. | V26: SGM SV Westheim / TSV Michelbach-Bilz / SV Rieden | W26: 9 | X26: 1.8 | Y26: KS
A27: 9. | B27: SG Bad Wimpfen II | C27: 24 | D27: 3 | F27: 9. | G27: SGM Oedheim Kochertal II (flex) | H27: 9 | I27: 1.125 | K27: 9. | L27: TSG Kirchberg/Jagst | M27: 15 | N27: 3 | P27: 1. | Q27: SGM Obersulm (flex) | R27: 16 | S27: 2.2857143 | T27: KS | U27: 4. | V27: SSV Schwäbisch Hall | W27: 6 | X27: 1 | Y27: KS
A28: 10. | B28: TV Flein | C28: neu | D28: neu | F28: 10. | G28: FSV Friedrichshaller SV II | H28: neu | I28: neu | P28: 2. | Q28: SSV Auenstein | R28: 15 | S28: 2.1428571 | T28: KS | U28: 5. | V28: SC Steinbach | W28: 6 | X28: 1 | Y28: KS
P29: 3. | Q29: SGM Eibensbach/Cleebronn/Botenheim/Stockheim II | R29: 14 | S29: 2 | T29: KS | U29: 6. | V29: SGM Ottendorf / Eutendorf / SG Rottal | W29: 3 | X29: 0.6 | Y29: KS
P30: 4. | Q30: SC Böckingen | R30: 10 | S30: 1.4285714 | T30: KS | U30: 7. | V30: SGM TSV Hessental/TSV Sulzdorf | W30: 3 | X30: 0.5 | Y30: KS
A31: SL: | B31: Franz Schmitt | F31: SL: | G31: Franz Schmitt | K31: SL: | L31: Christian Reuter | P31: 5. | Q31: SGM SG Stetten-Kleingartach/Oberes Leintal II (flex) | R31: 9 | S31: 1.2857143 | T31: KS | U31: 8. | V31: TSV Gaildorf (flex) zg. | W31: 0
A32: B-Junioren Kreisstaffel 4 | C32: Punkte | D32: Q | F32: B-Junioren Kreisstaffel 5 (Doppelrunde) | H32: Punkte | I32: Q | K32: B-Junioren Kreisstaffel 6 | M32: Punkte | N32: Q | P32: 6. | Q32: SGM Hausen Unteres Zabergäu II (flex) | R32: 7 | S32: 1
A33: 1. | B33: SGM TSV Pfedelbach/Jugendteam TSV II (flex) | C33: 6 | D33: 0.85714286 | F33: 1. | G33: TV Niederstetten (flex) | H33: 9 | I33: 1.2857143 | K33: 1. | L33: SGM Westgartshausen/ Tiefenbach/Kressberg/Goldbach/Satteldorf | M33: 6 | N33: 0.85714286 | P33: 7. | Q33: SV Heilbronn am Leinbach II | R33: 7 | S33: 1 | T33: KS | U33: 1. | V33: SGM VfR Altenmünster/SV Onolzheim | W33: 18 | X33: 2.5714286 | Y33: LS
A34: 2. | B34: SGM TSV Ohrnberg / Zweiflingen | C34: 1 | D34: 0.14285714 | F34: 2. | G34: SGM FC Creglingen/Bieberehren/Röttingen/Taubertal (flex) | H34: 4 | I34: 0.66666667 | K34: 2. | L34: TSV Ilshofen (flex) | M34: 3 | N34: 0.42857143 | P34: 8. | Q34: TSV Talheim (flex) | R34: 1 | S34: 0.14285714 | T34: KS | U34: 2. | V34: SGM FC Langenburg/Blaufelden/Braunsbach/Dünsbach I | W34: 15 | X34: 2.1428571 | Y34: LS
A35: 3. | B35: SGM VfB Neuhütten/Wüstenrot/Neulautern (flex) | C35: 7 | D35: 1.4 | F35: 3. | G35: SGM SV Wachbach/TSV Althausen-Neunkirchen (flex) | H35: 3 | I35: 0.42857143 | K35: 3. | L35: SGM FC Matzenbach/TSV Unterdeufstetten (flex) | M35: 1 | N35: 0.2 | U35: 3. | V35: SGM Gründelhardt-Oberspeltach/Honhardt/Obersontheim/Vellberg | W35: 15 | X35: 2.1428571 | Y35: KS
A36: 4. | B36: SGM TSV Niedernhall II / Kickers Mittleres Kochertal (flex) | C36: 3 | D36: 0.6 | F36: 4. | G36: SGM Weikersheim Vorbach-Tauber (flex) | H36: 0 | I36: 0 | K36: 4. | L36: SGM Ottendorf / Eutendorf / SG Rottal | M36: 3 | N36: 0.6 | P36: 1. | Q36: SG Bad Wimpfen II | R36: 24 | S36: 3 | T36: KS | U36: 4. | V36: SV Tüngental | W36: 15 | X36: 2.1428571 | Y36: LS
A37: 5. | B37: SGM FV Künzelsau/SV Morsbach/SC Amrichshausen (flex) | C37: 0 | D37: 0 | K37: 5. | L37: SGM TSV Hessental/TSV Sulzdorf | M37: 3 | N37: 0.5 | P37: 2. | Q37: SGM Union Heilbronn / TSN 1969 II | R37: 12 | S37: 1.5 | U37: 5. | V37: SGM SV Ingersheim/SSV Stimpfach | W37: 10 | X37: 1.4285714 | Y37: KS
A38: 6. | B38: SGM TSV Brettach KoBra (flex) | C38: 6 | D38: 0.75 | K38: 6. | L38: SGM VfL Mainhardt/Juniorteam MMB II | M38: 7 | N38: 1.4 | P38: 3. | Q38: SGM TSV Neudenau Unteres Jagsttal II (flex) | R38: 9 | S38: 1.125 | T38: KS | U38: 6. | V38: SGM Westgartshausen/ Tiefenbach/Kressberg/Goldbach/Satteldorf | W38: 6 | X38: 0.85714286 | Y38: KS
K39: 7. | L39: SSV Schwäbisch Hall | M39: 6 | N39: 1 | P39: 4. | Q39: SGM Oedheim Kochertal II (flex) | R39: 9 | S39: 1.125 | T39: KS | U39: 7. | V39: TSV Ilshofen (flex) | W39: 3 | X39: 0.42857143 | Y39: KS
K40: 8. | L40: SC Steinbach | M40: 6 | N40: 1 | P40: 5. | Q40: SGM TSV Brettach KoBra (flex) | R40: 6 | S40: 0.75 | T40: KS | U40: 8. | V40: SGM FC Matzenbach/TSV Unterdeufstetten (flex) | W40: 1 | X40: 0.2 | Y40: KS
...

Sheet C-Junioren
A1: Vorschlag Einteilung Rückrunde C-Junioren 2025/2026 | L1: Stand: 31.12.25 | Q1: keine Teilnahme Leistungsstaffel (Verzicht / flex / rückv. Spieler) | S1: LS | T1: =COUNTIF($T$6:T$52,S1) -> 10 | X1: LS | Y1: =COUNTIF($Y$6:$Y$52,X1) -> 10
Q2: Rückzug | S2: KS | T2: =COUNTIF($T$6:T$60,S2) -> 36 | X2: KS | Y2: =COUNTIF($Y$6:$Y$60,X2) -> 37
A3: SL: | B3: Peter Parys-Allweiler | F3: SL: | G3: Andreas Leitner | Q3: Änderung Mannschaftsstärke zur Rückrunde
A4: C-Junioren Leistungsstaffel 1 | C4: Punkte | D4: Q | F4: C-Junioren Leistungsstaffel 2 | H4: Punkte | I4: Q | Q4: stärkste Kreisstaffel
A5: 1. | B5: SG Bad Wimpfen | C5: =VLOOKUP(B5,$Q:$S,2,0) -> 19 | D5: =VLOOKUP(B5,$Q:$S,3,0) -> 2.7142857 | F5: 1. | G5: SGM FC Creglingen/Oberes Taubertal | H5: =VLOOKUP(G5,$V:$X,2,0) -> 21 | I5: =VLOOKUP(G5,$V:$X,3,0) -> 3 | Q5: Unterland | R5: Punkte | S5: Q | V5: Hohenlohe | W5: Punkte | X5: Q
A6: 2. | B6: SC Amorbach I | C6: =VLOOKUP(B6,$Q:$S,2,0) -> 15 | D6: =VLOOKUP(B6,$Q:$S,3,0) -> 2.1428571 | F6: 2. | G6: VfB Bad Mergentheim | H6: =VLOOKUP(G6,$V:$X,2,0) -> 18 | I6: =VLOOKUP(G6,$V:$X,3,0) -> 2.5714286 | P6: 1. | Q6: SG Bad Wimpfen | R6: 19 | S6: 2.7142857 | T6: LS | U6: 1. | V6: SGM FC Creglingen/Oberes Taubertal | W6: 21 | X6: 3 | Y6: LS
A7: 3. | B7: SGM Union Heilbronn / TSN 1969 II | C7: =VLOOKUP(B7,$Q:$S,2,0) -> 12 | D7: =VLOOKUP(B7,$Q:$S,3,0) -> 1.7142857 | F7: 3. | G7: SGM TSV Weißbach I / Kickers Mittleres Kochertal | H7: =VLOOKUP(G7,$V:$X,2,0) -> 19 | I7: =VLOOKUP(G7,$V:$X,3,0) -> 2.7142857 | P7: 2. | Q7: SC Amorbach I | R7: 15 | S7: 2.1428571 | T7: LS | U7: 2. | V7: VfB Bad Mergentheim | W7: 18 | X7: 2.5714286 | Y7: LS
A8: 4. | B8: SGM Dahenfeld/Oedheim I | C8: =VLOOKUP(B8,$Q:$S,2,0) -> 18 | D8: =VLOOKUP(B8,$Q:$S,3,0) -> 2.5714286 | F8: 4. | G8: SGM TSV Bitzfeld/Brettachtal I | H8: =VLOOKUP(G8,$V:$X,2,0) -> 16 | I8: =VLOOKUP(G8,$V:$X,3,0) -> 2.2857143 | P8: 3. | Q8: SGM Union Heilbronn / TSN 1969 II | R8: 12 | S8: 1.7142857 | T8: LS | U8: 3. | V8: TV Niederstetten | W8: 13 | X8: 1.8571429 | Y8: KS
A9: 5. | B9: SGM Tiefenbach H-U-T-H | C9: =VLOOKUP(B9,$Q:$S,2,0) -> 18 | D9: =VLOOKUP(B9,$Q:$S,3,0) -> 2.5714286 | F9: 5. | G9: SGM TSG Waldenburg/TSV Neuenstein I | H9: =VLOOKUP(G9,$V:$X,2,0) -> 15 | I9: =VLOOKUP(G9,$V:$X,3,0) -> 2.1428571 | P9: 4. | Q9: FSV Friedrichshaller SV | R9: 10 | S9: 1.4285714 | T9: KS | U9: 4. | V9: SV Mulfingen (flex) | W9: 12 | X9: 1.7142857 | Y9: KS
A10: 6. | B10: SGM Willsbach I | C10: =VLOOKUP(B10,$Q:$S,2,0) -> 13 | D10: =VLOOKUP(B10,$Q:$S,3,0) -> 1.8571429 | F10: 6. | G10: Spfr Schwäbisch Hall II | H10: =VLOOKUP(G10,$V:$X,2,0) -> 19 | I10: =VLOOKUP(G10,$V:$X,3,0) -> 2.7142857 | P10: 5. | Q10: SGM Heinsheim/Sommerberg | R10: 9 | S10: 1.2857143 | T10: KS | U10: 5. | V10: SGM TSV Althausen-Neunkirchen/SV Wachbach | W10: 7 | X10: 1 | Y10: KS
A11: 7. | B11: SGM Spvgg Möckmühl Unteres Jagsttal I | C11: =VLOOKUP(B11,$Q:$S,2,0) -> 12 | D11: =VLOOKUP(B11,$Q:$S,3,0) -> 1.7142857 | F11: 7. | G11: SGM TSV Sulzdorf/TSV Hessental I | H11: =VLOOKUP(G11,$V:$X,2,0) -> 18 | I11: =VLOOKUP(G11,$V:$X,3,0) -> 2.5714286 | P11: 6. | Q11: VfL Obereisesheim | R11: 7 | S11: 1 | T11: KS | U11: 6. | V11: 1. FC Igersheim | W11: 7 | X11: 1 | Y11: KS
A12: 8. | B12: SGM FSV Schwaigern/Oberes Leintal I | C12: =VLOOKUP(B12,$Q:$S,2,0) -> 21 | D12: =VLOOKUP(B12,$Q:$S,3,0) -> 3 | F12: 8. | G12: SGM TSV Michelbach/Bilz/SV Westheim/SV Rieden I | H12: =VLOOKUP(G12,$V:$X,2,0) -> 15 | I12: =VLOOKUP(G12,$V:$X,3,0) -> 2.1428571 | P12: 7. | Q12: TSG Heilbronn I | R12: 6 | S12: 0.85714286 | T12: KS | U12: 7. | V12: SGM Weikersheim Vorbach-Tauber (flex) | W12: 3 | X12: 0.42857143 | Y12: KS
A13: 9. | B13: SGM TSV Meimsheim Zabergäu | C13: =VLOOKUP(B13,$Q:$S,2,0) -> 16 | D13: =VLOOKUP(B13,$Q:$S,3,0) -> 2.2857143 | F13: 9. | G13: TSV Ilshofen | H13: =VLOOKUP(G13,$V:$X,2,0) -> 22 | I13: =VLOOKUP(G13,$V:$X,3,0) -> 2.75 | P13: 8. | Q13: SGM Gundelsheim Krumme Ebene am Neckar | R13: 0 | S13: 0 | T13: KS | U13: 8. | V13: SGM Billingsbach / Blaufelden / Wiesenbach | W13: 1 | X13: 0.14285714 | Y13: KS
A14: 10. | B14: SGM SC Ilsfeld/Abstatt/Beilstein/Heinriet ABI I | C14: =VLOOKUP(B14,$Q:$S,2,0) -> 13 | D14: =VLOOKUP(B14,$Q:$S,3,0) -> 1.8571429 | F14: 10. | G14: SGM Obersontheim/Vellberg/Gründelhardt/Honhardt I | H14: =VLOOKUP(G14,$V:$X,2,0) -> 19 | I14: =VLOOKUP(G14,$V:$X,3,0) -> 2.375
P15: 1. | Q15: SGM Dahenfeld/Oedheim I | R15: 18 | S15: 2.5714286 | T15: LS | U15: 1. | V15: SGM TSV Weißbach I / Kickers Mittleres Kochertal | W15: 19 | X15: 2.7142857 | Y15: LS
P16: 2. | Q16: SGM Tiefenbach H-U-T-H | R16: 18 | S16: 2.5714286 | T16: LS | U16: 2. | V16: SGM TSV Bitzfeld/Brettachtal I | W16: 16 | X16: 2.2857143 | Y16: LS
A17: SL: | B17: Dieter Schaaf | F17: SL: | G17: Dieter Schaaf | K17: SL: | L17: Peter Parys-Allweiler | P17: 3. | Q17: SGM Willsbach I | R17: 13 | S17: 1.8571429 | T17: LS | U17: 3. | V17: SGM TSG Waldenburg/TSV Neuenstein I | W17: 15 | X17: 2.1428571 | Y17: LS
A18: C-Junioren Kreisstaffel 1 | C18: Punkte | D18: Q | F18: C-Junioren Kreisstaffel 2 | H18: Punkte | I18: Q | K18: C-Junioren Kreisstaffel 3 | M18: Punkte | N18: Q | P18: 4. | Q18: SGM Spvgg Möckmühl Unteres Jagsttal I | R18: 12 | S18: 1.7142857 | T18: LS | U18: 4. | V18: SGM VfB Neuhütten/Wüstenrot/Neulautern | W18: 10 | X18: 1.4285714 | Y18: KS
A19: 1. | B19: FSV Friedrichshaller SV | C19: =VLOOKUP(B19,$Q:$S,2,0) -> 10 | D19: =VLOOKUP(B19,$Q:$S,3,0) -> 1.4285714 | F19: 1. | G19: TSG Heilbronn I | H19: =VLOOKUP(G19,$Q:$S,2,0) -> 6 | I19: =VLOOKUP(G19,$Q:$S,3,0) -> 0.85714286 | J19: qs1 | K19: 1. | L19: SV Leingarten | M19: =VLOOKUP(L19,$Q:$S,2,0) -> 3 | N19: =VLOOKUP(L19,$Q:$S,3,0) -> 0.42857143 | O19: qs3 | P19: 5. | Q19: SGM TSV Hardthausen KoBra | R19: 7 | S19: 1 | T19: KS | U19: 5. | V19: SGM DJK-TSV Bieringen/Schöntal | W19: 10 | X19: 1.4285714 | Y19: KS
A20: 2. | B20: SGM Heinsheim/Sommerberg | C20: =VLOOKUP(B20,$Q:$S,2,0) -> 9 | D20: =VLOOKUP(B20,$Q:$S,3,0) -> 1.2857143 | F20: 2. | G20: SGM TSV Erlenbach EbErG I | H20: =VLOOKUP(G20,$Q:$S,2,0) -> 6 | I20: =VLOOKUP(G20,$Q:$S,3,0) -> 0.85714286 | J20: qs2 | K20: 2. | L20: SGM Pfaffenhofen / Oberes Zabergäu | M20: =VLOOKUP(L20,$Q:$S,2,0) -> 0 | N20: =VLOOKUP(L20,$Q:$S,3,0) -> 0 | O20: qs3 | P20: 6. | Q20: SGM TSV Erlenbach EbErG I | R20: 6 | S20: 0.85714286 | T20: KS | U20: 6. | V20: TSG Öhringen | W20: 8 | X20: 1.1428571 | Y20: KS
A21: 3. | B21: VfL Obereisesheim | C21: =VLOOKUP(B21,$Q:$S,2,0) -> 7 | D21: =VLOOKUP(B21,$Q:$S,3,0) -> 1 | F21: 3. | G21: TSV Weinsberg | H21: =VLOOKUP(G21,$Q:$S,2,0) -> 6 | I21: =VLOOKUP(G21,$Q:$S,3,0) -> 0.85714286 | J21: qs2 | K21: 3. | L21: SGM FSV Schwaigern/Oberes Leintal II | M21: =VLOOKUP(L21,$Q:$S,2,0) -> 13 | N21: =VLOOKUP(L21,$Q:$S,3,0) -> 2.1666667 | O21: qs8 | P21: 7. | Q21: TSV Weinsberg | R21: 6 | S21: 0.85714286 | T21: KS | U21: 7. | V21: SGM TSV Zweiflingen/Ohrnberg | W21: 3 | X21: 0.42857143 | Y21: KS
A22: 4. | B22: SGM TSV Hardthausen KoBra | C22: =VLOOKUP(B22,$Q:$S,2,0) -> 7 | D22: =VLOOKUP(B22,$Q:$S,3,0) -> 1 | F22: 4. | G22: TSV Talheim (flex) | H22: =VLOOKUP(G22,$Q:$S,2,0) -> 18 | I22: =VLOOKUP(G22,$Q:$S,3,0) -> 3 | J22: qs9 | K22: 4. | L22: SGM MassenbachHausen (flex) | M22: =VLOOKUP(L22,$Q:$S,2,0) -> 11 | N22: =VLOOKUP(L22,$Q:$S,3,0) -> 1.8333333 | O22: qs8 | P22: 8. | Q22: SC Amorbach II | R22: 3 | S22: 0.42857143 | T22: KS | U22: 8. | V22: SGM FV Künzelsau / SV Morsbach / SC Amrichshausen | W22: 0 | X22: 0 | Y22: KS
A23: 5. | B23: TV Flein | C23: =VLOOKUP(B23,$Q:$S,2,0) -> 12 | D23: =VLOOKUP(B23,$Q:$S,3,0) -> 1.7142857 | F23: 5. | G23: Aramäer Heilbronn | H23: 15 | I23: 2.5 | J23: qs9 | K23: 5. | L23: SGM Nordhausen Unteres Zabergäu | M23: =VLOOKUP(L23,$Q:$S,2,0) -> 10 | N23: =VLOOKUP(L23,$Q:$S,3,0) -> 1.6666667 | O23: qs8
A24: 6. | B24: TG Böckingen | C24: =VLOOKUP(B24,$Q:$S,2,0) -> 10 | D24: =VLOOKUP(B24,$Q:$S,3,0) -> 1.4285714 | F24: 6. | G24: SGM Auenstein/Untergruppenbach | H24: =VLOOKUP(G24,$Q:$S,2,0) -> 10 | I24: =VLOOKUP(G24,$Q:$S,3,0) -> 1.6666667 | J24: qs9 | K24: 6. | L24: SGM Kirchhausen (flex) | M24: 6 | N24: 1 | O24: qs8 | P24: 1. | Q24: SGM FSV Schwaigern/Oberes Leintal I | R24: 21 | S24: 3 | T24: LS | U24: 1. | V24: Spfr Schwäbisch Hall II | W24: 19 | X24: 2.7142857 | Y24: LS
A25: 7. | B25: Spfr Lauffen | C25: =VLOOKUP(B25,$Q:$S,2,0) -> 7 | D25: =VLOOKUP(B25,$Q:$S,3,0) -> 1 | F25: 7. | G25: SV Heilbronn am Leinbach III | H25: =VLOOKUP(G25,$Q:$S,2,0) -> 10 | I25: =VLOOKUP(G25,$Q:$S,3,0) -> 1.6666667 | J25: qs9 | K25: 7. | L25: SGM Botenheim/Cleebronn/Eibensbach/Stockheim II (flex) | M25: =VLOOKUP(L25,$Q:$S,2,0) -> 3 | N25: =VLOOKUP(L25,$Q:$S,3,0) -> 0.5 | O25: qs8 | P25: 2. | Q25: SGM TSV Meimsheim Zabergäu | R25: 16 | S25: 2.2857143 | T25: LS | U25: 2. | V25: SGM TSV Sulzdorf/TSV Hessental I | W25: 18 | X25: 2.5714286 | Y25: LS
A26: 8. | B26: SV Heilbronn am Leinbach II | C26: 18 | D26: 3 | F26: 8. | G26: SC Böckingen (flex) | H26: =VLOOKUP(G26,$Q:$S,2,0) -> 1 | I26: =VLOOKUP(G26,$Q:$S,3,0) -> 0.16666667 | J26: qs9 | K26: 8. | L26: SGM Güglingen/Frauenzimmern (flex) | M26: =VLOOKUP(L26,$Q:$S,2,0) -> 0 | N26: =VLOOKUP(L26,$Q:$S,3,0) -> 0 | O26: qs8 | P26: 3. | Q26: SGM SC Ilsfeld/Abstatt/Beilstein/Heinriet ABI I | R26: 13 | S26: 1.8571429 | T26: LS | U26: 3. | V26: SGM TSV Michelbach/Bilz/SV Westheim/SV Rieden I | W26: 15 | X26: 2.1428571 | Y26: LS
A27: 9. | B27: SGM Löwenstein Sulmtal | C27: 16 | D27: 2.67 | F27: 9. | G27: Sport-Union Neckarsulm II | H27: =VLOOKUP(G27,$Q:$S,2,0) -> neu | I27: =VLOOKUP(G27,$Q:$S,3,0) -> neu | P27: 4. | Q27: TV Flein | R27: 12 | S27: 1.7142857 | T27: KS | U27: 4. | V27: SC Steinbach | W27: 12 | X27: 1.7142857 | Y27: KS
A28: 10. | B28: VfR Heilbronn 96/18 III | C28: neu | D28: neu | P28: 5. | Q28: TG Böckingen | R28: 10 | S28: 1.4285714 | T28: KS | U28: 5. | V28: SSV Schwäbisch Hall I | W28: 7 | X28: 1 | Y28: KS
P29: 6. | Q29: Spfr Lauffen | R29: 7 | S29: 1 | T29: KS | U29: 6. | V29: SGM Fichtenberg/Rottal | W29: 6 | X29: 0.85714286 | Y29: KS
P30: 7. | Q30: SV Leingarten | R30: 3 | S30: 0.42857143 | T30: KS | U30: 7. | V30: SGM Eutendorf/Ottendorf | W30: 6 | X30: 0.85714286 | Y30: KS
A31: SL: | B31: Peter Parys-Allweiler | F31: SL: | G31: Andreas Leitner | K31: SL: | L31: Andreas Leitner | P31: 8. | Q31: SGM Pfaffenhofen / Oberes Zabergäu | R31: 0 | S31: 0 | T31: KS | U31: 8. | V31: TSV Gaildorf | W31: 0 | X31: 0 | Y31: KS
A32: C-Junioren Kreisstaffel 4 | C32: Punkte | D32: Q | F32: C-Junioren Kreisstaffel 5 | H32: Punkte | I32: Q | K32: C-Junioren Kreisstaffel 6 | M32: Punkte | N32: Q | P32: xxx | Q32: xxxxxxxxxxxxxxxxxxxxxxxxxxxxxxxxxxxxxxxxxxxxx | R32: xxxxxx | S32: xxxx
A33: 1. | B33: SGM Gundelsheim Krumme Ebene am Neckar | C33: =VLOOKUP(B33,$Q:$S,2,0) -> 0 | D33: =VLOOKUP(B33,$Q:$S,3,0) -> 0 | E33: qs1 | F33: 1. | G33: TV Niederstetten | H33: =VLOOKUP(G33,$V:$X,2,0) -> 13 | I33: =VLOOKUP(G33,$V:$X,3,0) -> 1.8571429 | J33: qs4 | K33: 1. | L33: TSG Öhringen | M33: =VLOOKUP(L33,$V:$X,2,0) -> 8 | N33: =VLOOKUP(L33,$V:$X,3,0) -> 1.1428571 | O33: qs4 | P33: 1. | Q33: SV Heilbronn am Leinbach II | R33: 18 | S33: 3 | T33: KS | U33: 1. | V33: TSV Ilshofen | W33: 22 | X33: 2.75 | Y33: LS
A34: 2. | B34: SC Amorbach II | C34: =VLOOKUP(B34,$Q:$S,2,0) -> 3 | D34: =VLOOKUP(B34,$Q:$S,3,0) -> 0.42857143 | E34: qs2 | F34: 2. | G34: SV Mulfingen (flex) | H34: =VLOOKUP(G34,$V:$X,2,0) -> 12 | I34: =VLOOKUP(G34,$V:$X,3,0) -> 1.7142857 | J34: qs4 | K34: 2. | L34: SGM TSV Zweiflingen/Ohrnberg (flex) | M34: 3 | N34: 0.42857143 | O34: qs4 | P34: 2. | Q34: SGM FSV Schwaigern/Oberes Leintal II | R34: 13 | S34: 2.1666667 | T34: KS | U34: 2. | V34: SGM Obersontheim/Vellberg/Gründelhardt/Honhardt I | W34: 19 | X34: 2.375 | Y34: LS
A35: 3. | B35: TSG Heilbronn II | C35: =VLOOKUP(B35,$Q:$S,2,0) -> 6 | D35: =VLOOKUP(B35,$Q:$S,3,0) -> 1 | E35: qs9 | F35: 3. | G35: SGM VfB Neuhütten/Wüstenrot/Neulautern | H35: =VLOOKUP(G35,$V:$X,2,0) -> 10 | I35: =VLOOKUP(G35,$V:$X,3,0) -> 1.4285714 | J35: qs5 | K35: 3. | L35: SGM FV Künzelsau / SV Morsbach / SC Amrichshausen | M35: =VLOOKUP(L35,$V:$X,2,0) -> 0 | N35: =VLOOKUP(L35,$V:$X,3,0) -> 0 | O35: qs4 | P35: 3. | Q35: SGM MassenbachHausen (flex) | R35: 11 | S35: 1.8333333 | T35: KS | U35: 3. | V35: SGM Rot am See/Brettheim/Hengstfeld | W35: 16 | X35: 2 | Y35: KS
A36: 4. | B36: SGM Union Heilbronn / TSN 1969 III (flex) | C36: =VLOOKUP(B36,$Q:$S,2,0) -> 1 | D36: =VLOOKUP(B36,$Q:$S,3,0) -> 0.16666667 | E36: qs9 | F36: 4. | G36: SGM DJK-TSV Bieringen/Schöntal | H36: =VLOOKUP(G36,$V:$X,2,0) -> 10 | I36: =VLOOKUP(G36,$V:$X,3,0) -> 1.4285714 | J36: qs5 | K36: 4. | L36: SGM SSV Gaisbach/Kupferzell/Ingelfingen II | M36: =VLOOKUP(L36,$V:$X,2,0) -> 18 | N36: =VLOOKUP(L36,$V:$X,3,0) -> 3 | O36: qs11 | P36: 4. | Q36: SGM Nordhausen Unteres Zabergäu | R36: 10 | S36: 1.6666667 | T36: KS | U36: 4. | V36: SGM VfR Altenmünster/SV Onolzheim | W36: 14 | X36: 1.75 | Y36: KS
A37: 5. | B37: SGM Spvgg Möckmühl Unteres Jagsttal II | C37: =VLOOKUP(B37,$Q:$S,2,0) -> 12 | D37: =VLOOKUP(B37,$Q:$S,3,0) -> 2 | E37: qs10 | F37: 5. | G37: SC Steinbach | H37: =VLOOKUP(G37,$V:$X,2,0) -> 12 | I37: =VLOOKUP(G37,$V:$X,3,0) -> 1.7142857 | J37: qs6 | K37: 5. | L37: SC Michelbach/Wald | M37: =VLOOKUP(L37,$V:$X,2,0) -> 13 | N37: =VLOOKUP(L37,$V:$X,3,0) -> 2.1666667 | O37: qs11 | P37: 5. | Q37: SGM Kirchhausen | R37: 6 | S37: 1 | T37: KS | U37: 5. | V37: SGM TSV Gerabronn/Dünsbach/Langenburg | W37: 12 | X37: 1.5 | Y37: KS
A38: 6. | B38: SGM Neuenstadt | C38: =VLOOKUP(B38,$Q:$S,2,0) -> 7 | D38: =VLOOKUP(B38,$Q:$S,3,0) -> 1.1666667 | E38: qs10 | F38: 6. | G38: SSV Schwäbisch Hall I | H38: =VLOOKUP(G38,$V:$X,2,0) -> 7 | I38: =VLOOKUP(G38,$V:$X,3,0) -> 1 | J38: qs6 | K38: 6. | L38: SGM TSV Weißbach II / Kickers Mittleres Kochertal | M38: =VLOOKUP(L38,$V:$X,2,0) -> 10 | N38: =VLOOKUP(L38,$V:$X,3,0) -> 1.6666667 | O38: qs11 | P38: 6. | Q38: SGM Botenheim/Cleebronn/Eibensbach/Stockheim II (flex) | R38: 3 | S38: 0.5 | T38: KS | U38: 6. | V38: SGM SV Ingersheim/SSV Stimpfach | W38: 10 | X38: 1.25 | Y38: KS
A39: 7. | B39: SGM TSV Erlenbach EbErG II (flex) | C39: =VLOOKUP(B39,$Q:$S,2,0) -> 6 | D39: =VLOOKUP(B39,$Q:$S,3,0) -> 1 | E39: qs10 | F39: 7. | G39: SGM Rot am See/Brettheim/Hengstfeld | H39: =VLOOKUP(G39,$V:$X,2,0) -> 16 | I39: =VLOOKUP(G39,$V:$X,3,0) -> 2 | J39: qs7 | K39: 7. | L39: SGM TSG Waldenburg/TSV Neuenstein II (flex) | M39: =VLOOKUP(L39,$V:$X,2,0) -> 10 | N39: =VLOOKUP(L39,$V:$X,3,0) -> 1.6666667 | O39: qs11 | P39: 7. | Q39: SGM Güglingen/Frauenzimmern (flex) | R39: 0 | S39: 0 | T39: KS | U39: 7. | V39: TSG Kirchberg/Jagst I | W39: 6 | X39: 0.75 | Y39: KS
A40: 8. | B40: SGM Dahenfeld/Oedheim II (flex) | C40: =VLOOKUP(B40,$Q:$S,2,0) -> 4 | D40: =VLOOKUP(B40,$Q:$S,3,0) -> 0.66666667 | E40: qs10 | F40: 8. | G40: SGM VfR Altenmünster/SV Onolzheim | H40: =VLOOKUP(G40,$V:$X,2,0) -> 14 | I40: =VLOOKUP(G40,$V:$X,3,0) -> 1.75 | J40: qs7 | K40: 8. | L40: SGM TSV Pfedelbach/Jugendteam TSV II (flex) | M40: =VLOOKUP(L40,$V:$X,2,0) -> 0 | N40: =VLOOKUP(L40,$V:$X,3,0) -> 0 | O40: qs11 | U40: 8. | V40: SGM SpVgg Gammesfeld/Bartenstein/Schrozberg | W40: 5 | X40: 0.625 | Y40: KS
...

Sheet D-Junioren
A1: Vorschlag Einteilung Rückrunde D-Junioren 2025/2026 | L1: Stand: 07.01.26 | Q1: keine Teilnahme Leistungsstaffel (Verzicht / flex / rückv. Spieler) | S1: BS | T1: =COUNTIF($T$8:$T$120,S1) -> 10 | X1: BS | Y1: =COUNTIF($Y$8:$Y$120,X1) -> 8
Q2: Rückzug | S2: LS | T2: =COUNTIF($T$8:$T$120,S2) -> 8 | X2: LS | Y2: =COUNTIF($Y$8:$Y$120,X2) -> 8
A3: SL: | B3: Alexander Ergenzinger | F3: SL: | G3: Michael Schmelzle | Q3: Änderung Mannschaftsstärke zur Rückrunde | S3: KS1 | T3: =COUNTIF($T$8:$T$120,S3) -> 32 | U3: 4x8 | X3: KS | Y3: =COUNTIF($Y$8:$Y$120,X3) -> 17
A4: D-Junioren Bezirksstaffel 1 | C4: Punkte | D4: Q | F4: D-Junioren Bezirksstaffel 2 | H4: Punkte | I4: Q | S4: KS2 | T4: =COUNTIF($T$8:$T$120,S4) -> 32 | U4: 4x8 | X4: KS2 | Y4: =COUNTIF($Y$8:$Y$120,X4) -> 0
A5: 1. | B5: SG Bad Wimpfen I | C5: =VLOOKUP(B5,$Q:$S,2,0) -> 16 | D5: =VLOOKUP(B5,$Q:$S,3,0) -> 2.6666667 | E5: qs1 | F5: 1. | G5: SGM TSV Ohrnberg / Zweiflingen I | H5: =VLOOKUP(G5,$V:$X,2,0) -> 16 | I5: =VLOOKUP(G5,$V:$X,3,0) -> 2.6666667 | S5: KS7er | T5: =COUNTIF($T$8:$T$120,S5) -> 6 | U5: 1x6 | X5: KS3 | Y5: =COUNTIF($Y$8:$Y$120,X5) -> 5
A6: 2. | B6: SGM Union Heilbronn / TSN 1969 I | C6: =VLOOKUP(B6,$Q:$S,2,0) -> 13 | D6: =VLOOKUP(B6,$Q:$S,3,0) -> 2.1666667 | E6: qs1 | F6: 2. | G6: TSG Öhringen I | H6: =VLOOKUP(G6,$V:$X,2,0) -> 14 | I6: =VLOOKUP(G6,$V:$X,3,0) -> 2.3333333
A7: 3. | B7: VfR Heilbronn 96/18 II | C7: =VLOOKUP(B7,$Q:$S,2,0) -> 21 | D7: =VLOOKUP(B7,$Q:$S,3,0) -> 3 | E7: qs2 | F7: 3. | G7: SGM TSV Waldbach/Brettachtal I | H7: =VLOOKUP(G7,$V:$X,2,0) -> 13 | I7: =VLOOKUP(G7,$V:$X,3,0) -> 2.1666667 | Q7: Unterland | R7: Punkte | S7: Q | V7: Hohenlohe | W7: Punkte | X7: Q
A8: 4. | B8: Sport-Union Neckarsulm I | C8: =VLOOKUP(B8,$Q:$S,2,0) -> 18 | D8: =VLOOKUP(B8,$Q:$S,3,0) -> 2.5714286 | E8: qs2 | F8: 4. | G8: SGM Krautheim/Mittleres Jagsttal I | H8: =VLOOKUP(G8,$V:$X,2,0) -> 10 | I8: =VLOOKUP(G8,$V:$X,3,0) -> 2 | P8: 1 | Q8: SG Bad Wimpfen I | R8: 16 | S8: 2.6666667 | T8: BS | U8: 1 | V8: SGM TSV Ohrnberg / Zweiflingen I | W8: 16 | X8: 2.6666667 | Y8: BS
A9: 5. | B9: SGM Oedheim/Dahenfeld I | C9: =VLOOKUP(B9,$Q:$S,2,0) -> 15 | D9: =VLOOKUP(B9,$Q:$S,3,0) -> 2.1428571 | E9: qs2 | F9: 5. | G9: SGM SSV Gaisbach/TSVKupferzell/TSV Ingelfingen I | H9: =VLOOKUP(G9,$V:$X,2,0) -> 7 | I9: =VLOOKUP(G9,$V:$X,3,0) -> 1.4 | P9: 2 | Q9: SGM Union Heilbronn / TSN 1969 I | R9: 13 | S9: 2.1666667 | T9: BS | U9: 2 | V9: TSG Öhringen I | W9: 14 | X9: 2.3333333 | Y9: BS
A10: 6. | B10: SGM Ilsfeld-Abstatt-Heinriet ABI I | C10: =VLOOKUP(B10,$Q:$S,2,0) -> 15 | D10: =VLOOKUP(B10,$Q:$S,3,0) -> 2.5 | E10: qs3 | F10: 6. | G10: SGM Weikersheim Vorbach-Tauber I | H10: =VLOOKUP(G10,$V:$X,2,0) -> 16 | I10: =VLOOKUP(G10,$V:$X,3,0) -> 2.6666667 | P10: 3 | Q10: VfR Heilbronn 96/18 III | R10: 11 | S10: 1.8333333 | T10: LS | U10: 3 | V10: SGM TSV Waldbach/Brettachtal I | W10: 13 | X10: 2.1666667 | Y10: BS
A11: 7. | B11: SGM Sülzbach Sulmtal I | C11: =VLOOKUP(B11,$Q:$S,2,0) -> 13 | D11: =VLOOKUP(B11,$Q:$S,3,0) -> 2.1666667 | E11: qs3 | F11: 7. | G11: TV Niederstetten I | H11: =VLOOKUP(G11,$V:$X,2,0) -> 14 | I11: =VLOOKUP(G11,$V:$X,3,0) -> 2.3333333 | P11: 4 | Q11: FSV Friedrichshaller SV I | R11: 10 | S11: 1.6666667 | T11: LS | U11: 4 | V11: SGM TSV Pfedelbach/Jugendteam TSV I | W11: 9 | X11: 1.5 | Y11: LS
A12: 8. | B12: SV Heilbronn am Leinbach I | C12: =VLOOKUP(B12,$Q:$S,2,0) -> 18 | D12: =VLOOKUP(B12,$Q:$S,3,0) -> 2.5714286 | E12: qs4 | F12: 8. | G12: SGM Taubertal/Röttingen | H12: =VLOOKUP(G12,$V:$X,2,0) -> 13 | I12: =VLOOKUP(G12,$V:$X,3,0) -> 2.1666667 | P12: 5 | Q12: SGM Untergriesheim H-U-T-H I | R12: 5 | S12: 0.83333333 | T12: KS1 | U12: 5 | V12: SGM TSV Neuenstein/Waldenburg I | W12: 6 | X12: 1 | Y12: LS
A13: 9. | B13: FSV Schwaigern I | C13: =VLOOKUP(B13,$Q:$S,2,0) -> 18 | D13: =VLOOKUP(B13,$Q:$S,3,0) -> 3 | E13: qs5 | P13: 6 | Q13: SC Amorbach I (U13) | R13: 4 | S13: 0.66666667 | T13: KS1 | U13: 6 | V13: SGM TG Forchtenberg II / Kickers Mittleres Kochertal | W13: 3 | X13: 0.5 | Y13: LS
A14: 10. | B14: SGM VfL Brackenheim I | C14: =VLOOKUP(B14,$Q:$S,2,0) -> 10 | D14: =VLOOKUP(B14,$Q:$S,3,0) -> 1.6666667 | E14: qs5 | P14: 7 | Q14: SGM Bachenau Krumme Ebene am Neckar | R14: 0 | S14: 0 | T14: KS1 | U14: 7 | V14: TSG Verrenberg | W14: 0 | X14: 0 | Y14: KS
A16: SL: | B16: Alexander Ergenzinger | F16: SL: | G16: Michael Schmelzle | P16: 1 | Q16: VfR Heilbronn 96/18 II | R16: 21 | S16: 3 | T16: BS | U16: 1 | V16: SGM TG Forchtenberg I / Kickers Mittleres Kochertal | W16: 15 | X16: 3 | Y16: Talentrunde
A17: D-Junioren Leistungsstaffel 1 | C17: Punkte | D17: Q | F17: D-Junioren Leistungsstaffel 2 | H17: Punkte | I17: Q | P17: 2 | Q17: Sport-Union Neckarsulm I | R17: 18 | S17: 2.5714286 | T17: BS | U17: 2 | V17: SGM Krautheim/Mittleres Jagsttal I | W17: 10 | X17: 2 | Y17: BS
A18: 1. | B18: VfR Heilbronn 96/18 III | C18: =VLOOKUP(B18,$Q:$S,2,0) -> 11 | D18: =VLOOKUP(B18,$Q:$S,3,0) -> 1.8333333 | E18: qs1 | F18: 1. | G18: SGM TSV Pfedelbach/Jugendteam TSV I | H18: =VLOOKUP(G18,$V:$X,2,0) -> 9 | I18: =VLOOKUP(G18,$V:$X,3,0) -> 1.5 | P18: 3 | Q18: SGM Oedheim/Dahenfeld I | R18: 15 | S18: 2.1428571 | T18: BS | U18: 3 | V18: SGM SSV Gaisbach/TSVKupferzell/TSV Ingelfingen I | W18: 7 | X18: 1.4 | Y18: BS
A19: 2. | B19: FSV Friedrichshaller SV I | C19: =VLOOKUP(B19,$Q:$S,2,0) -> 10 | D19: =VLOOKUP(B19,$Q:$S,3,0) -> 1.6666667 | E19: qs1 | F19: 2. | G19: SGM TSV Neuenstein/Waldenburg I | H19: =VLOOKUP(G19,$V:$X,2,0) -> 6 | I19: =VLOOKUP(G19,$V:$X,3,0) -> 1 | P19: 4 | Q19: SGM TSV Brettach KoBra I | R19: 12 | S19: 1.7142857 | T19: LS | U19: 4 | V19: SV Mulfingen | W19: 7 | X19: 1.4 | Y19: LS
A20: 3. | B20: SGM TSV Brettach KoBra I | C20: =VLOOKUP(B20,$Q:$S,2,0) -> 12 | D20: =VLOOKUP(B20,$Q:$S,3,0) -> 1.7142857 | E20: qs2 | F20: 3. | G20: SGM TG Forchtenberg II / Kickers Mittleres Kochertal | H20: =VLOOKUP(G20,$V:$X,2,0) -> 3 | I20: =VLOOKUP(G20,$V:$X,3,0) -> 0.5 | P20: 5 | Q20: SGM VfL Eberstadt | R20: 9 | S20: 1.2857143 | T20: KS1 | U20: 5 | V20: SGM DJK-TSV Bieringen/Schöntal I | W20: 4 | X20: 0.8 | Y20: LS
A21: 4. | B21: TV Flein I | C21: =VLOOKUP(B21,$Q:$S,2,0) -> 12 | D21: =VLOOKUP(B21,$Q:$S,3,0) -> 2 | E21: qs3 | F21: 4. | G21: SV Mulfingen | H21: =VLOOKUP(G21,$V:$X,2,0) -> 7 | I21: =VLOOKUP(G21,$V:$X,3,0) -> 1.4 | P21: 6 | Q21: TSV Weinsberg I | R21: 6 | S21: 0.85714286 | T21: KS1 | U21: 6 | V21: FV Künzelsau I | W21: 0 | X21: 0 | Y21: KS
A22: 5. | B22: TSV Untergruppenbach | C22: =VLOOKUP(B22,$Q:$S,2,0) -> 10 | D22: =VLOOKUP(B22,$Q:$S,3,0) -> 1.6666667 | E22: qs3 | F22: 5. | G22: SGM DJK-TSV Bieringen/Schöntal I | H22: =VLOOKUP(G22,$V:$X,2,0) -> 4 | I22: =VLOOKUP(G22,$V:$X,3,0) -> 0.8 | P22: 7 | Q22: TSG Bretzfeld-Rappach | R22: 3 | S22: 0.42857143 | T22: KS1
A23: 6. | B23: SGM Union Heilbronn / TSN 1969 II | C23: =VLOOKUP(B23,$Q:$S,2,0) -> 13 | D23: =VLOOKUP(B23,$Q:$S,3,0) -> 1.8571429 | E23: qs4 | F23: 6. | G23: VfB Bad Mergentheim I | H23: =VLOOKUP(G23,$V:$X,2,0) -> 9 | I23: =VLOOKUP(G23,$V:$X,3,0) -> 1.5 | P23: 8 | Q23: Spvgg Möckmühl I | R23: 0 | S23: 0 | T23: KS1 | U23: 1 | V23: SGM Weikersheim Vorbach-Tauber I | W23: 16 | X23: 2.6666667 | Y23: BS
A24: 7. | B24: ASV Heilbronn | C24: =VLOOKUP(B24,$Q:$S,2,0) -> 12 | D24: =VLOOKUP(B24,$Q:$S,3,0) -> 1.7142857 | E24: qs4 | F24: 7. | G24: SGM SV Wachbach/Althausen Neunkirchen | H24: =VLOOKUP(G24,$V:$X,2,0) -> 4 | I24: =VLOOKUP(G24,$V:$X,3,0) -> 0.66666667 | U24: 2 | V24: TV Niederstetten I | W24: 14 | X24: 2.3333333 | Y24: BS
A25: 8. | B25: SV Heilbronn am Leinbach II | C25: =VLOOKUP(B25,$Q:$S,2,0) -> 10 | D25: =VLOOKUP(B25,$Q:$S,3,0) -> 1.6666667 | E25: qs5 | F25: 8. | G25: SGM VfB Neuhütten/Wüstenrot/Neulautern | H25: =VLOOKUP(G25,$V:$X,2,0) -> 15 | I25: =VLOOKUP(G25,$V:$X,3,0) -> 3 | P25: 1 | Q25: SGM Ilsfeld-Abstatt-Heinriet ABI I | R25: 15 | S25: 2.5 | T25: BS | U25: 3 | V25: SGM Taubertal/Röttingen | W25: 13 | X25: 2.1666667 | Y25: BS
P26: 2 | Q26: SGM Sülzbach Sulmtal I | R26: 13 | S26: 2.1666667 | T26: BS | U26: 4 | V26: VfB Bad Mergentheim I | W26: 9 | X26: 1.5 | Y26: LS
A27: SL: | B27: Alexander Ergenzinger | F27: SL: | G27: Alexander Ergenzinger | K27: SL: | L27: Dieter Schaaf | P27: 3 | Q27: TV Flein I | R27: 12 | S27: 2 | T27: LS | U27: 5 | V27: SGM SV Wachbach/Althausen Neunkirchen | W27: 4 | X27: 0.66666667 | Y27: LS
A28: D-Junioren Kreisstaffel 01 | C28: Punkte | D28: Q | F28: D-Junioren Kreisstaffel 02 | H28: Punkte | I28: Q | K28: D-Junioren Kreisstaffel 03 | M28: Punkte | N28: Q | P28: 4 | Q28: TSV Untergruppenbach | R28: 10 | S28: 1.6666667 | T28: LS | U28: 6 | V28: 1. FC Igersheim | W28: 3 | X28: 0.5 | Y28: LS
A29: 1 | B29: SGM Untergriesheim H-U-T-H I | C29: =VLOOKUP(B29,$Q:$S,2,0) -> 5 | D29: =VLOOKUP(B29,$Q:$S,3,0) -> 0.83333333 | E29: qs1 | F29: 1 | G29: SGM VfL Eberstadt | H29: =VLOOKUP(G29,$Q:$S,2,0) -> 9 | I29: =VLOOKUP(G29,$Q:$S,3,0) -> 1.2857143 | J29: qs2 | K29: 8 | L29: TGV Eintracht Beilstein I | M29: =VLOOKUP(L29,$Q:$S,2,0) -> 9 | N29: =VLOOKUP(L29,$Q:$S,3,0) -> 1.5 | O29: qs3 | P29: 5 | Q29: TGV Eintracht Beilstein I | R29: 9 | S29: 1.5 | T29: KS1 | U29: 7 | V29: SGM FC Creglingen/Bieberehren I | W29: 1 | X29: 0.16666667 | Y29: KS
A30: 7 | B30: SC Amorbach I (U13) | C30: =VLOOKUP(B30,$Q:$S,2,0) -> 4 | D30: =VLOOKUP(B30,$Q:$S,3,0) -> 0.66666667 | E30: qs1 | F30: 8 | G30: TSV Weinsberg I | H30: =VLOOKUP(G30,$Q:$S,2,0) -> 6 | I30: =VLOOKUP(G30,$Q:$S,3,0) -> 0.85714286 | J30: qs2 | K30: 1 | L30: TG Böckingen I | M30: =VLOOKUP(L30,$Q:$S,2,0) -> 9 | N30: =VLOOKUP(L30,$Q:$S,3,0) -> 1.2857143 | O30: qs4 | P30: 6 | Q30: Spfr Neckarwestheim I | R30: 3 | S30: 0.5 | T30: KS1 | U30: xxx | V30: xxxxxxxxxxxxxxxxxxxxxxxxxxxxxxxxxxxxxxxxxxxxx | W30: xxxxxx | X30: xxxx
A31: 3 | B31: SGM Bachenau Krumme Ebene am Neckar | C31: =VLOOKUP(B31,$Q:$S,2,0) -> 0 | D31: =VLOOKUP(B31,$Q:$S,3,0) -> 0 | E31: qs1 | F31: 4 | G31: TSG Bretzfeld-Rappach | H31: =VLOOKUP(G31,$Q:$S,2,0) -> 3 | I31: =VLOOKUP(G31,$Q:$S,3,0) -> 0.42857143 | J31: qs2 | K31: 4 | L31: TSG Heilbronn I | M31: =VLOOKUP(L31,$Q:$S,2,0) -> 7 | N31: =VLOOKUP(L31,$Q:$S,3,0) -> 1 | O31: qs4 | P31: 7 | Q31: SGM Willsbach I | R31: 0 | S31: 0 | T31: KS1 | U31: 1 | V31: VfB Bad Mergentheim II | W31: 13 | X31: 2.1666667 | Y31: KS
A32: 5 | B32: Spvgg Möckmühl I | C32: =VLOOKUP(B32,$Q:$S,2,0) -> 0 | D32: =VLOOKUP(B32,$Q:$S,3,0) -> 0 | E32: qs2 | F32: 2 | G32: SGM Willsbach I | H32: =VLOOKUP(G32,$Q:$S,2,0) -> 0 | I32: =VLOOKUP(G32,$Q:$S,3,0) -> 0 | J32: qs3 | K32: 5 | L32: TSV Talheim | M32: =VLOOKUP(L32,$Q:$S,2,0) -> 3 | N32: =VLOOKUP(L32,$Q:$S,3,0) -> 0.42857143 | O32: qs4 | U32: 2 | V32: SGM FC Creglingen/Bieberehren II | W32: 10 | X32: 1.6666667 | Y32: KS
A33: 4 | B33: SGM Neuenstadt I | C33: =VLOOKUP(B33,$Q:$S,2,0) -> 15 | D33: =VLOOKUP(B33,$Q:$S,3,0) -> 2.5 | E33: ks q1 | F33: 3 | G33: SGM Bonfeld/Fürfeld/Obergimpern I | H33: =VLOOKUP(G33,$Q:$S,2,0) -> 8 | I33: =VLOOKUP(G33,$Q:$S,3,0) -> 1.3333333 | J33: qs4 | K33: 2 | L33: TV Flein II | M33: =VLOOKUP(L33,$Q:$S,2,0) -> 18 | N33: =VLOOKUP(L33,$Q:$S,3,0) -> 2.5714286 | O33: ks q4 | P33: 1 | Q33: VfR Heilbronn 96/18 I | R33: 21 | S33: 3 | U33: 3 | V33: SGM Weikersheim Vorbach-Tauber II | W33: 9 | X33: 1.5 | Y33: KS
A34: 2 | B34: Sport-Union Neckarsulm II | C34: =VLOOKUP(B34,$Q:$S,2,0) -> 19 | D34: =VLOOKUP(B34,$Q:$S,3,0) -> 2.7142857 | E34: ks q2 | F34: 5 | G34: TSV Erlenbach I | H34: =VLOOKUP(G34,$Q:$S,2,0) -> 18 | I34: =VLOOKUP(G34,$Q:$S,3,0) -> 3 | J34: ks q1 | K34: 3 | L34: SSV Auenstein | M34: =VLOOKUP(L34,$Q:$S,2,0) -> 16 | N34: =VLOOKUP(L34,$Q:$S,3,0) -> 2.2857143 | O34: ks q4 | P34: 2 | Q34: SV Heilbronn am Leinbach I | R34: 18 | S34: 2.5714286 | T34: BS | U34: 4 | V34: TV Niederstetten II | W34: 3 | X34: 0.5 | Y34: KS
A35: 8 | B35: SGM Neudenau/Siglingen | C35: =VLOOKUP(B35,$Q:$S,2,0) -> 17 | D35: =VLOOKUP(B35,$Q:$S,3,0) -> 2.4285714 | E35: ks q2 | F35: 6 | G35: SV Heilbronn am Leinbach III | H35: =VLOOKUP(G35,$Q:$S,2,0) -> 13 | I35: =VLOOKUP(G35,$Q:$S,3,0) -> 2.1666667 | J35: ks q3 | K35: 7 | L35: Spfr Neckarwestheim II | M35: =VLOOKUP(L35,$Q:$S,2,0) -> 15 | N35: =VLOOKUP(L35,$Q:$S,3,0) -> 2.1428571 | O35: ks q4 | P35: 3 | Q35: SGM Union Heilbronn / TSN 1969 II | R35: 13 | S35: 1.8571429 | T35: LS
A36: 6 | B36: SGM Oedheim/Dahenfeld II | C36: =VLOOKUP(B36,$Q:$S,2,0) -> 15 | D36: =VLOOKUP(B36,$Q:$S,3,0) -> 2.1428571 | E36: ks q2 | F36: 7 | G36: FC Kirchhausen | H36: =VLOOKUP(G36,$Q:$S,2,0) -> 19 | I36: =VLOOKUP(G36,$Q:$S,3,0) -> 2.7142857 | J36: ks q4 | K36: 6 | L36: SV Leingarten II | M36: =VLOOKUP(L36,$Q:$S,2,0) -> 13 | N36: =VLOOKUP(L36,$Q:$S,3,0) -> 2.1666667 | O36: ks q5 | P36: 4 | Q36: ASV Heilbronn | R36: 12 | S36: 1.7142857 | T36: LS | U36: 1 | V36: SGM SSV Gaisbach/TSV Kupferzell/TSV Ingelfingen II | W36: 12 | X36: 2.4 | Y36: KS
P37: 5 | Q37: TG Böckingen I | R37: 9 | S37: 1.2857143 | T37: KS1 | U37: 2 | V37: SGM Amrichshausen/Morsbach/Nagelsberg | W37: 12 | X37: 2.4 | Y37: KS
P38: 6 | Q38: TSG Heilbronn I | R38: 7 | S38: 1 | T38: KS1 | U38: 3 | V38: SGM TG Forchtenberg III / Kickers Mittleres Kochertal | W38: 7 | X38: 1.4 | Y38: KS
A39: SL: | B39: Dieter Schaaf | F39: SL: | G39: Alexander Ergenzinger | K39: SL: | L39: Alexander Ergenzinger | P39: 7 | Q39: TSV Talheim | R39: 3 | S39: 0.42857143 | T39: KS1 | U39: 4 | V39: SGM DJK-TSV Bieringen/Schöntal II | W39: 6 | X39: 1.2 | Y39: KS
A40: D-Junioren Kreisstaffel 04 | C40: Punkte | D40: Q | F40: D-Junioren Kreisstaffel 05 | H40: Punkte | I40: Q | K40: D-Junioren Kreisstaffel 06 | M40: Punkte | N40: Q | P40: 8 | Q40: Aramäer Heilbronn | R40: 0 | S40: 0 | U40: 5 | V40: SGM TSV Ohrnberg / Zweiflingen II | W40: 4 | X40: 0.8 | Y40: KS3
A41: 7 | B41: Spfr Neckarwestheim I | C41: =VLOOKUP(B41,$Q:$S,2,0) -> 3 | D41: =VLOOKUP(B41,$Q:$S,3,0) -> 0.5 | E41: qs3 | F41: 7 | G41: SC Amorbach II (U12) | H41: =VLOOKUP(G41,$Q:$S,2,0) -> 12 | I41: =VLOOKUP(G41,$Q:$S,3,0) -> 2 | J41: ks q1 | K41: 2 | L41: TV Flein III | M41: =VLOOKUP(L41,$Q:$S,2,0) -> 12 | N41: =VLOOKUP(L41,$Q:$S,3,0) -> 2 | O41: ks q3 | U41: 6 | V41: SGM Krautheim/Mittleres Jagsttal II | W41: 3 | X41: 0.6 | Y41: KS
...

Sheet E-Junioren
A1: Vorschlag Einteilung Rückrunde E-Junioren 2025/2026 | L1: Stand: 31.12.25 | Q1: Rückzug | S1: KS1-1 | T1: =COUNTIF($T$10:$T$169,S1) -> 8 | U1: 1 | X1: KS1-1 | Y1: =COUNTIF($Y$10:$Y$130,X1) -> 14
S2: KS1-2 | T2: =COUNTIF($T$10:$T$169,S2) -> 8 | U2: 1 | X2: KS1-2 | Y2: =COUNTIF($Y$10:$Y$130,X2) -> 11
A3: SL: | B3: Reiner Falk | F3: SL: | G3: Reiner Falk | K3: SL: | L3: Reiner Falk | S3: KS1-3 | T3: =COUNTIF($T$10:$T$169,S3) -> 16 | U3: 2 | X3: KS2 | Y3: =COUNTIF($Y$10:$Y$130,X3) -> 29
A4: E-Junioren Kreisstaffel 01 | C4: Punkte | D4: Q | F4: E-Junioren Kreisstaffel 02 | H4: Punkte | I4: Q | K4: E-Junioren Kreisstaffel 03 | M4: Punkte | N4: Q | S4: KS2-1 | T4: =COUNTIF($T$10:$T$169,S4) -> 16 | U4: 2 | Y4: =COUNTIF($Y$10:$Y$130,X4) -> 0
A5: 1. | B5: SG Bad Wimpfen I | C5: =VLOOKUP(B5,$Q:$S,2,0) -> 10 | D5: =VLOOKUP(B5,$Q:$S,3,0) -> 2 | F5: 1. | G5: FSV Friedrichshaller SV I | H5: =VLOOKUP(G5,$Q:$S,2,0) -> 9 | I5: =VLOOKUP(G5,$Q:$S,3,0) -> 1.8 | K5: 1. | L5: Spvgg Oedheim I | M5: =VLOOKUP(L5,$Q:$S,2,0) -> 8 | N5: =VLOOKUP(L5,$Q:$S,3,0) -> 1.6 | S5: KS2-2 | T5: =COUNTIF($T$10:$T$169,S5) -> 45 | Y5: =COUNTIF($Y$10:$Y$130,X5) -> 0
A6: 2. | B6: SC Amorbach I | C6: =VLOOKUP(B6,$Q:$S,2,0) -> 15 | D6: =VLOOKUP(B6,$Q:$S,3,0) -> 3 | F6: 2. | G6: SGM TSV Hardthausen KoBra I | H6: =VLOOKUP(G6,$Q:$S,2,0) -> 12 | I6: =VLOOKUP(G6,$Q:$S,3,0) -> 2.4 | K6: 2. | L6: SC Amorbach II | M6: =VLOOKUP(L6,$Q:$S,2,0) -> 5 | N6: =VLOOKUP(L6,$Q:$S,3,0) -> 1 | S6: KS2-3 | T6: =COUNTIF($T$10:$T$169,S6) -> 31 | U6: 10 | Y6: =COUNTIF($Y$10:$Y$130,X6) -> 0
A7: 3. | B7: TSV Erlenbach I | C7: =VLOOKUP(B7,$Q:$S,2,0) -> 13 | D7: =VLOOKUP(B7,$Q:$S,3,0) -> 2.6 | F7: 3. | G7: SV Sülzbach I | H7: =VLOOKUP(G7,$Q:$S,2,0) -> 10 | I7: =VLOOKUP(G7,$Q:$S,3,0) -> 2 | K7: 3. | L7: TG Offenau I | M7: =VLOOKUP(L7,$Q:$S,2,0) -> 5 | N7: =VLOOKUP(L7,$Q:$S,3,0) -> 1
A8: 4. | B8: Spfr Neckarwestheim I | C8: =VLOOKUP(B8,$Q:$S,2,0) -> 15 | D8: =VLOOKUP(B8,$Q:$S,3,0) -> 3 | F8: 4. | G8: FC Obersulm I | H8: =VLOOKUP(G8,$Q:$S,2,0) -> 9 | I8: =VLOOKUP(G8,$Q:$S,3,0) -> 1.8 | K8: 4. | L8: TSV Heinsheim | M8: =VLOOKUP(L8,$Q:$S,2,0) -> 4 | N8: =VLOOKUP(L8,$Q:$S,3,0) -> 0.8
A9: 5. | B9: TGV Eintracht Beilstein I | C9: =VLOOKUP(B9,$Q:$S,2,0) -> 12 | D9: =VLOOKUP(B9,$Q:$S,3,0) -> 2.4 | F9: 5. | G9: SGM SC Abstatt Heinriet I | H9: =VLOOKUP(G9,$Q:$S,2,0) -> 9 | I9: =VLOOKUP(G9,$Q:$S,3,0) -> 1.8 | K9: 5. | L9: Sport-Union Neckarsulm I | M9: =VLOOKUP(L9,$Q:$S,2,0) -> 9 | N9: =VLOOKUP(L9,$Q:$S,3,0) -> 1.8 | Q9: Unterland | R9: Punkte | S9: Q | V9: Hohenlohe | W9: Punkte | X9: Q
A10: 6. | B10: VfR Heilbronn 96/18 | C10: =VLOOKUP(B10,$Q:$S,2,0) -> 15 | D10: =VLOOKUP(B10,$Q:$S,3,0) -> 3 | F10: 6. | G10: SV Leingarten I | H10: =VLOOKUP(G10,$Q:$S,2,0) -> 9 | I10: =VLOOKUP(G10,$Q:$S,3,0) -> 1.8 | K10: 6. | L10: SGM Neudenau/Siglingen I | M10: =VLOOKUP(L10,$Q:$S,2,0) -> 6 | N10: =VLOOKUP(L10,$Q:$S,3,0) -> 1.2 | P10: 1 | Q10: SG Bad Wimpfen I | R10: 10 | S10: 2 | T10: KS1-1 | U10: 1 | V10: 1. FC Igersheim I | W10: 12 | X10: 3 | Y10: KS1-1
A11: 7. | B11: SGM TSV Meimsheim I | C11: =VLOOKUP(B11,$Q:$S,2,0) -> 12 | D11: =VLOOKUP(B11,$Q:$S,3,0) -> 2.4 | F11: 7. | G11: TSG Heilbronn I | H11: =VLOOKUP(G11,$Q:$S,2,0) -> 10 | I11: =VLOOKUP(G11,$Q:$S,3,0) -> 2 | K11: 7. | L11: Spvgg Möckmühl I | M11: =VLOOKUP(L11,$Q:$S,2,0) -> 3 | N11: =VLOOKUP(L11,$Q:$S,3,0) -> 0.6 | P11: 2 | Q11: FSV Friedrichshaller SV I | R11: 9 | S11: 1.8 | T11: KS1-2 | U11: 2 | V11: SGM Weikersheim Vorbach-Tauber I | W11: 9 | X11: 2.25 | Y11: KS1-1
A12: 8. | B12: TG Böckingen I | C12: =VLOOKUP(B12,$Q:$S,2,0) -> 12 | D12: =VLOOKUP(B12,$Q:$S,3,0) -> 2.4 | F12: 8. | G12: SV Heilbronn am Leinbach I | H12: =VLOOKUP(G12,$Q:$S,2,0) -> 9 | I12: =VLOOKUP(G12,$Q:$S,3,0) -> 1.8 | K12: 8. | L12: SGM Union Heilbronn / TSN 1969 II | M12: =VLOOKUP(L12,$Q:$S,2,0) -> 3 | N12: =VLOOKUP(L12,$Q:$S,3,0) -> 0.6 | P12: 3 | Q12: Spvgg Oedheim I | R12: 8 | S12: 1.6 | T12: KS1-3 | U12: 3 | V12: SGM SV Edelfingen/SV Oberbalbach/DJK Unterbalbach I | W12: 6 | X12: 1.5 | Y12: KS1-1
P13: 4 | Q13: SC Amorbach II | R13: 5 | S13: 1 | T13: KS1-3 | U13: 4 | V13: SGM Röttingen/Taubertal | W13: 3 | X13: 0.75 | Y13: KS1-2
P14: 5 | Q14: TG Offenau I | R14: 5 | S14: 1 | T14: KS1-3 | U14: 5 | V14: VfB Bad Mergentheim I | W14: 0 | X14: 0 | Y14: KS1-2
A15: SL: | B15: Reiner Falk | F15: SL: | G15: Reiner Falk | K15: SL: | L15: Reiner Falk | P15: 6 | Q15: TSV Heinsheim | R15: 4 | S15: 0.8 | T15: KS1-3
A16: E-Junioren Kreisstaffel 04 | C16: Punkte | D16: Q | F16: E-Junioren Kreisstaffel 05 | H16: Punkte | I16: Q | K16: E-Junioren Kreisstaffel 06 | M16: Punkte | N16: Q | U16: 1 | V16: SGM SV Wachbach/TSV Althausen-Neunkirchen I | W16: 12 | X16: 3 | Y16: KS1-1
A17: 1. | B17: SGM Eberstadt/Gellmersbach I | C17: =VLOOKUP(B17,$Q:$S,2,0) -> 9 | D17: =VLOOKUP(B17,$Q:$S,3,0) -> 1.8 | F17: 1. | G17: FSV Friedrichshaller SV II | H17: =VLOOKUP(G17,$Q:$S,2,0) -> 15 | I17: =VLOOKUP(G17,$Q:$S,3,0) -> 3 | K17: 1. | L17: TV Flein I | M17: =VLOOKUP(L17,$Q:$S,2,0) -> 15 | N17: =VLOOKUP(L17,$Q:$S,3,0) -> 3 | P17: 1 | Q17: SC Amorbach I | R17: 15 | S17: 3 | T17: KS1-1 | U17: 2 | V17: SGM VfR Gommersdorf/TSV Krautheim I | W17: 9 | X17: 2.25 | Y17: KS1-1
A18: 2. | B18: TSV Talheim I | C18: =VLOOKUP(B18,$Q:$S,2,0) -> 3 | D18: =VLOOKUP(B18,$Q:$S,3,0) -> 0.6 | F18: 2. | G18: VfL Obereisesheim II | H18: =VLOOKUP(G18,$Q:$S,2,0) -> 12 | I18: =VLOOKUP(G18,$Q:$S,3,0) -> 2.4 | K18: 2. | L18: Spfr Neckarwestheim II | M18: =VLOOKUP(L18,$Q:$S,2,0) -> 12 | N18: =VLOOKUP(L18,$Q:$S,3,0) -> 2.4 | P18: 2 | Q18: SGM TSV Hardthausen KoBra I | R18: 12 | S18: 2.4 | T18: KS1-2 | U18: 3 | V18: SGM Dörzbach/Klepsau/Hohebach I | W18: 6 | X18: 1.5 | Y18: KS1-1
A19: 3. | B19: SC Ilsfeld I | C19: =VLOOKUP(B19,$Q:$S,2,0) -> 6 | D19: =VLOOKUP(B19,$Q:$S,3,0) -> 1.2 | F19: 3. | G19: SGM Gundelsheim Krumme Ebene am Neckar II | H19: =VLOOKUP(G19,$Q:$S,2,0) -> 12 | I19: =VLOOKUP(G19,$Q:$S,3,0) -> 2.4 | K19: 3. | L19: SSV Auenstein I | M19: =VLOOKUP(L19,$Q:$S,2,0) -> 9 | N19: =VLOOKUP(L19,$Q:$S,3,0) -> 1.8 | P19: 3 | Q19: Sport-Union Neckarsulm I | R19: 9 | S19: 1.8 | T19: KS1-3 | U19: 4 | V19: SV Mulfingen | W19: 3 | X19: 0.75 | Y19: KS1-2
A20: 4. | B20: SGM Lehrensteinsfeld | C20: =VLOOKUP(B20,$Q:$S,2,0) -> 3 | D20: =VLOOKUP(B20,$Q:$S,3,0) -> 0.6 | F20: 4. | G20: SC Dahenfeld | H20: =VLOOKUP(G20,$Q:$S,2,0) -> 15 | I20: =VLOOKUP(G20,$Q:$S,3,0) -> 3 | K20: 4. | L20: SGM FV Wüstenrot/Neuhütten/Neulautern | M20: =VLOOKUP(L20,$Q:$S,2,0) -> 10 | N20: =VLOOKUP(L20,$Q:$S,3,0) -> 2 | P20: 4 | Q20: SGM Neudenau/Siglingen I | R20: 6 | S20: 1.2 | T20: KS1-3 | U20: 5 | V20: TV Niederstetten | W20: 0 | X20: 0 | Y20: KS1-2
A21: 5. | B21: Spfr Lauffen I | C21: =VLOOKUP(B21,$Q:$S,2,0) -> 3 | D21: =VLOOKUP(B21,$Q:$S,3,0) -> 0.6 | F21: 5. | G21: SG Bad Wimpfen II | H21: =VLOOKUP(G21,$Q:$S,2,0) -> 12 | I21: =VLOOKUP(G21,$Q:$S,3,0) -> 2.4 | K21: 5. | L21: SGM Nordheim Unteres Zabergäu I | M21: =VLOOKUP(L21,$Q:$S,2,0) -> 15 | N21: =VLOOKUP(L21,$Q:$S,3,0) -> 3 | P21: 5 | Q21: Spvgg Möckmühl I | R21: 3 | S21: 0.6 | T21: KS1-3
A22: 6. | B22: FC Kirchhausen I | C22: =VLOOKUP(B22,$Q:$S,2,0) -> 3 | D22: =VLOOKUP(B22,$Q:$S,3,0) -> 0.6 | F22: 6. | G22: SGM Neuenstadt I | H22: =VLOOKUP(G22,$Q:$S,2,0) -> 15 | I22: =VLOOKUP(G22,$Q:$S,3,0) -> 3 | K22: 6. | L22: TSV Pfaffenhofen | M22: =VLOOKUP(L22,$Q:$S,2,0) -> 15 | N22: =VLOOKUP(L22,$Q:$S,3,0) -> 3 | P22: 6 | Q22: SGM Untergriesheim H-U-T-H I | R22: 0 | S22: 0 | T22: KS2-2 | U22: 1 | V22: SGM Sindringen/Ernsbach I - Kickers Mittleres Kochertal | W22: 12 | X22: 3 | Y22: KS1-1
A23: 7. | B23: Aramäer Heilbronn I | C23: =VLOOKUP(B23,$Q:$S,2,0) -> 7 | D23: =VLOOKUP(B23,$Q:$S,3,0) -> 1.4 | F23: 7. | G23: TSV Ellhofen I | H23: =VLOOKUP(G23,$Q:$S,2,0) -> 15 | I23: =VLOOKUP(G23,$Q:$S,3,0) -> 3 | K23: 7. | L23: SGM Cleebronn/Botenheim/Eibensbach/Stockheim I | M23: =VLOOKUP(L23,$Q:$S,2,0) -> 12 | N23: =VLOOKUP(L23,$Q:$S,3,0) -> 3 | U23: 2 | V23: SGM TSV Ingelfingen/Nagelsberg I | W23: 9 | X23: 2.25 | Y23: KS1-1
A24: 8. | B24: SGM Union Heilbronn / TSN 1969 I | C24: =VLOOKUP(B24,$Q:$S,2,0) -> 6 | D24: =VLOOKUP(B24,$Q:$S,3,0) -> 1.2 | F24: 8. | G24: SGM Bonfeld/Fürfeld/Obergimpern I | H24: =VLOOKUP(G24,$Q:$S,2,0) -> 12 | I24: =VLOOKUP(G24,$Q:$S,3,0) -> 2.4 | K24: 8. | L24: Aramäer Heilbronn II | M24: =VLOOKUP(L24,$Q:$S,2,0) -> 13 | N24: =VLOOKUP(L24,$Q:$S,3,0) -> 2.6 | P24: 1 | Q24: TSV Erlenbach I | R24: 13 | S24: 2.6 | T24: KS1-1 | U24: 3 | V24: SGM DJK-TSV Bieringen/Schöntal I | W24: 6 | X24: 1.5 | Y24: KS1-1
P25: 2 | Q25: SV Sülzbach I | R25: 10 | S25: 2 | T25: KS1-2 | U25: 4 | V25: FV Künzelsau I | W25: 3 | X25: 0.75 | Y25: KS1-2
P26: 3 | Q26: FC Obersulm I | R26: 9 | S26: 1.8 | T26: KS1-2 | U26: 5 | V26: SGM Amrichshausen/Morsbach | W26: 0 | X26: 0 | Y26: KS1-2
A27: SL: | B27: Ewald Blind | F27: SL: | G27: Ewald Blind | K27: SL: | L27: Ewald Blind | P27: 4 | Q27: SGM Eberstadt/Gellmersbach I | R27: 9 | S27: 1.8 | T27: KS1-3
A28: E-Junioren Kreisstaffel 07 | C28: Punkte | D28: Q | F28: E-Junioren Kreisstaffel 08 | H28: Punkte | I28: Q | K28: E-Junioren Kreisstaffel 09 | M28: Punkte | N28: Q | P28: 5 | Q28: TSV Talheim I | R28: 3 | S28: 0.6 | T28: KS1-3 | U28: 1 | V28: SGM TSV Zweiflingen/Ohrnberg I | W28: 9 | X28: 2.25 | Y28: KS1-1
A29: 1. | B29: SC Amorbach III | C29: =VLOOKUP(B29,$Q:$S,2,0) -> 6 | D29: =VLOOKUP(B29,$Q:$S,3,0) -> 1.2 | F29: 1. | G29: TSV Weinsberg I | H29: =VLOOKUP(G29,$Q:$S,2,0) -> 0 | I29: =VLOOKUP(G29,$Q:$S,3,0) -> 0 | K29: 1. | L29: Sport-Union Neckarsulm II | M29: =VLOOKUP(L29,$Q:$S,2,0) -> 7 | N29: =VLOOKUP(L29,$Q:$S,3,0) -> 1.4 | P29: 6 | Q29: TSV Weinsberg I | R29: 0 | S29: 0 | T29: KS2-2 | U29: 2 | V29: SSV Gaisbach I | W29: 7 | X29: 1.75 | Y29: KS1-1
A30: 2. | B30: SGM Untergriesheim H-U-T-H I | C30: =VLOOKUP(B30,$Q:$S,2,0) -> 0 | D30: =VLOOKUP(B30,$Q:$S,3,0) -> 0 | F30: 2. | G30: TSV Löwenstein | H30: =VLOOKUP(G30,$Q:$S,2,0) -> 0 | I30: =VLOOKUP(G30,$Q:$S,3,0) -> 0 | K30: 2. | L30: ASV Heilbronn I | M30: =VLOOKUP(L30,$Q:$S,2,0) -> 0 | N30: =VLOOKUP(L30,$Q:$S,3,0) -> 0 | U30: 3 | V30: SGM TSV Neuenstein/Waldenburg I | W30: 5 | X30: 1.25 | Y30: KS1-2
A31: 3. | B31: TSV Duttenberg I | C31: =VLOOKUP(B31,$Q:$S,2,0) -> 9 | D31: =VLOOKUP(B31,$Q:$S,3,0) -> 1.8 | F31: 3. | G31: TGV Eintracht Beilstein II | H31: =VLOOKUP(G31,$Q:$S,2,0) -> 8 | I31: =VLOOKUP(G31,$Q:$S,3,0) -> 1.6 | K31: 3. | L31: VfL Obereisesheim I | M31: =VLOOKUP(L31,$Q:$S,2,0) -> 6 | N31: =VLOOKUP(L31,$Q:$S,3,0) -> 1.2 | P31: 1 | Q31: Spfr Neckarwestheim I | R31: 15 | S31: 3 | T31: KS1-1 | U31: 4 | V31: SC Michelbach/Wald I | W31: 4 | X31: 1 | Y31: KS1-2
A32: 4. | B32: SGM Neuenstadt II | C32: =VLOOKUP(B32,$Q:$S,2,0) -> 15 | D32: =VLOOKUP(B32,$Q:$S,3,0) -> 3 | F32: 4. | G32: TSV Ellhofen II | H32: =VLOOKUP(G32,$Q:$S,2,0) -> 12 | I32: =VLOOKUP(G32,$Q:$S,3,0) -> 2.4 | K32: 4. | L32: TSG Heilbronn II | M32: =VLOOKUP(L32,$Q:$S,2,0) -> 12 | N32: =VLOOKUP(L32,$Q:$S,3,0) -> 2.4 | P32: 2 | Q32: TGV Eintracht Beilstein I | R32: 12 | S32: 2.4 | T32: KS1-1 | U32: 5 | V32: TSV Kupferzell I | W32: 3 | X32: 0.75 | Y32: KS1-2
A33: 5. | B33: FSV Friedrichshaller SV III | C33: =VLOOKUP(B33,$Q:$S,2,0) -> 6 | D33: =VLOOKUP(B33,$Q:$S,3,0) -> 1.2 | F33: 5. | G33: TSV Talheim II | H33: =VLOOKUP(G33,$Q:$S,2,0) -> 9 | I33: =VLOOKUP(G33,$Q:$S,3,0) -> 1.8 | K33: 5. | L33: TG Böckingen II | M33: =VLOOKUP(L33,$Q:$S,2,0) -> 11 | N33: =VLOOKUP(L33,$Q:$S,3,0) -> 2.2 | P33: 3 | Q33: SGM SC Abstatt Heinriet I | R33: 9 | S33: 1.8 | T33: KS1-2
